Workbook

Sheet Dashboard
A1: SpieleIDs
A2: {=_xlfn.LET( _xlpm.Kat,Dashboard!$M$2, _xlpm.Xraw,Dashboard!$M$3, _xlpm.DRaw,Dashboard!$M$4, _xlpm.IstAlleKat,AND(ISTEXT(_xlpm.Kat),LOWER(_xlpm.Kat)="alle"), _xlpm.IstAlleX,AND(ISTEXT(_xlpm.Xraw),LOWER(_xlpm.Xraw)="alle"), _xlpm.IDs0,DataSpiele!$A$2:$A$99814, _xlpm.Kats0,DataSpiele!$B$2:$B$99814, _xlpm.Dat0,DataSpiele!$C$2:$C$99814, _xlpm.IDs,_xlfn._xlws.FILTER(_xlpm.IDs0,_xlpm.IDs0<>""), _xlpm.Kats,_xlfn._xlws.FILTER(_xlpm.Kats0,_xlpm.IDs0<>""), _xlpm.Dat,_xlfn._xlws.FILTER(_xlpm.Dat0,_xlpm.IDs0<>""), _xlpm.DMin,IF(_xlpm.DRaw="","",IFERROR(--_xlpm.DRaw,DATEVALUE(_xlpm.DRaw))), _xlpm.HatDatum,_xlpm.DRaw<>"", _xlpm.IDsGef,_xlfn._xlws.FILTER( _xlpm.IDs, (IF(_xlpm.IstAlleKat,TRUE,_xlpm.Kats=_xlpm.Kat)) * (IF(_xlpm.HatDatum,_xlpm.Dat>=_xlpm.DMin,TRUE)) ), _xlpm.n,ROWS(_xlpm.IDsGef), _xlpm.X,IF(_xlpm.IstAlleX,_xlpm.n,IFERROR(--_xlpm.Xraw,VALUE(_xlpm.Xraw))), _xlpm.k,MIN(_xlpm.X,_xlpm.n), INDEX(_xlpm.IDsGef,_xlfn.SEQUENCE(_xlpm.k,1,_xlpm.n-_xlpm.k+1,1)) )} | C2: Statistics | L2: Spieltyp | M2: Alle
C3: Main Squad | E3: Games | F3: Goals | G3: Assists | H3: Contributions | I3: MOTM | J3: Avg. Rating | L3: Die letzten Spiele | M3: alle
C4: A. Russo | E4: {=SUMPRODUCT( --(DataSpieler!$C$2:$C$97619=$C4), --(DataSpieler!$E$2:$E$97619>0), --ISNUMBER(MATCH(DataSpieler!$A$2:$A$97619,_xlfn.ANCHORARRAY($A$2),0)) )} | F4: {=SUMPRODUCT( DataSpieler!$F$2:$F$97619, --(DataSpieler!$C$2:$C$97619=C4), --ISNUMBER(MATCH(DataSpieler!$A$2:$A$97619,_xlfn.ANCHORARRAY($A$2),0)) )} | G4: {=SUMPRODUCT( DataSpieler!$G$2:$G$97619, --(DataSpieler!$C$2:$C$97619=C4), --ISNUMBER(MATCH(DataSpieler!$A$2:$A$97619,_xlfn.ANCHORARRAY($A$2),0)) )} | H4: =F4+G4 | I4: {=SUMPRODUCT( --(DataSpieler!$C$2:$C$97619=C4), --(DataSpieler!$H$2:$H$97619="x"), --ISNUMBER(MATCH(DataSpieler!$A$2:$A$97619,_xlfn.ANCHORARRAY($A$2),0)) )} | J4: {=IFERROR( AVERAGE( _xlfn._xlws.FILTER( DataSpieler!$E$2:$E$97619, (DataSpieler!$C$2:$C$97619=C4) * ISNUMBER(MATCH(DataSpieler!$A$2:$A$97619,_xlfn.ANCHORARRAY($A$2),0)) ) ), "" )} | L4: Startdatum?
C5: F. Totti | E5: {=SUMPRODUCT( --(DataSpieler!$C$2:$C$97619=$C5), --(DataSpieler!$E$2:$E$97619>0), --ISNUMBER(MATCH(DataSpieler!$A$2:$A$97619,_xlfn.ANCHORARRAY($A$2),0)) )} | F5: {=SUMPRODUCT( DataSpieler!$F$2:$F$97619, --(DataSpieler!$C$2:$C$97619=C5), --ISNUMBER(MATCH(DataSpieler!$A$2:$A$97619,_xlfn.ANCHORARRAY($A$2),0)) )} | G5: {=SUMPRODUCT( DataSpieler!$G$2:$G$97619, --(DataSpieler!$C$2:$C$97619=C5), --ISNUMBER(MATCH(DataSpieler!$A$2:$A$97619,_xlfn.ANCHORARRAY($A$2),0)) )} | H5: =F5+G5 | I5: {=SUMPRODUCT( --(DataSpieler!$C$2:$C$97619=C5), --(DataSpieler!$H$2:$H$97619="x"), --ISNUMBER(MATCH(DataSpieler!$A$2:$A$97619,_xlfn.ANCHORARRAY($A$2),0)) )} | J5: {=IFERROR( AVERAGE( _xlfn._xlws.FILTER( DataSpieler!$E$2:$E$97619, (DataSpieler!$C$2:$C$97619=C5) * ISNUMBER(MATCH(DataSpieler!$A$2:$A$97619,_xlfn.ANCHORARRAY($A$2),0)) ) ), "" )}
C6: Vini Jr. | E6: {=SUMPRODUCT( --(DataSpieler!$C$2:$C$97619=$C6), --(DataSpieler!$E$2:$E$97619>0), --ISNUMBER(MATCH(DataSpieler!$A$2:$A$97619,_xlfn.ANCHORARRAY($A$2),0)) )} | F6: {=SUMPRODUCT( DataSpieler!$F$2:$F$97619, --(DataSpieler!$C$2:$C$97619=C6), --ISNUMBER(MATCH(DataSpieler!$A$2:$A$97619,_xlfn.ANCHORARRAY($A$2),0)) )} | G6: {=SUMPRODUCT( DataSpieler!$G$2:$G$97619, --(DataSpieler!$C$2:$C$97619=C6), --ISNUMBER(MATCH(DataSpieler!$A$2:$A$97619,_xlfn.ANCHORARRAY($A$2),0)) )} | H6: =F6+G6 | I6: {=SUMPRODUCT( --(DataSpieler!$C$2:$C$97619=C6), --(DataSpieler!$H$2:$H$97619="x"), --ISNUMBER(MATCH(DataSpieler!$A$2:$A$97619,_xlfn.ANCHORARRAY($A$2),0)) )} | J6: {=IFERROR( AVERAGE( _xlfn._xlws.FILTER( DataSpieler!$E$2:$E$97619, (DataSpieler!$C$2:$C$97619=C6) * ISNUMBER(MATCH(DataSpieler!$A$2:$A$97619,_xlfn.ANCHORARRAY($A$2),0)) ) ), "" )} | M6: letzte SpielID der Kategorie
C7: Jairzinho | E7: {=SUMPRODUCT( --(DataSpieler!$C$2:$C$97619=$C7), --(DataSpieler!$E$2:$E$97619>0), --ISNUMBER(MATCH(DataSpieler!$A$2:$A$97619,_xlfn.ANCHORARRAY($A$2),0)) )} | F7: {=SUMPRODUCT( DataSpieler!$F$2:$F$97619, --(DataSpieler!$C$2:$C$97619=C7), --ISNUMBER(MATCH(DataSpieler!$A$2:$A$97619,_xlfn.ANCHORARRAY($A$2),0)) )} | G7: {=SUMPRODUCT( DataSpieler!$G$2:$G$97619, --(DataSpieler!$C$2:$C$97619=C7), --ISNUMBER(MATCH(DataSpieler!$A$2:$A$97619,_xlfn.ANCHORARRAY($A$2),0)) )} | H7: =F7+G7 | I7: {=SUMPRODUCT( --(DataSpieler!$C$2:$C$97619=C7), --(DataSpieler!$H$2:$H$97619="x"), --ISNUMBER(MATCH(DataSpieler!$A$2:$A$97619,_xlfn.ANCHORARRAY($A$2),0)) )} | J7: {=IFERROR( AVERAGE( _xlfn._xlws.FILTER( DataSpieler!$E$2:$E$97619, (DataSpieler!$C$2:$C$97619=C7) * ISNUMBER(MATCH(DataSpieler!$A$2:$A$97619,_xlfn.ANCHORARRAY($A$2),0)) ) ), "" )} | L7: Squadbattles | M7: {=IFERROR(RIGHT(LOOKUP( 2, 1/(DataSpiele!B:B=Dashboard!L7), DataSpiele!A:A ),3),"000")}
C8: F. Valverde | E8: {=SUMPRODUCT( --(DataSpieler!$C$2:$C$97619=$C8), --(DataSpieler!$E$2:$E$97619>0), --ISNUMBER(MATCH(DataSpieler!$A$2:$A$97619,_xlfn.ANCHORARRAY($A$2),0)) )} | F8: {=SUMPRODUCT( DataSpieler!$F$2:$F$97619, --(DataSpieler!$C$2:$C$97619=C8), --ISNUMBER(MATCH(DataSpieler!$A$2:$A$97619,_xlfn.ANCHORARRAY($A$2),0)) )} | G8: {=SUMPRODUCT( DataSpieler!$G$2:$G$97619, --(DataSpieler!$C$2:$C$97619=C8), --ISNUMBER(MATCH(DataSpieler!$A$2:$A$97619,_xlfn.ANCHORARRAY($A$2),0)) )} | H8: =F8+G8 | I8: {=SUMPRODUCT( --(DataSpieler!$C$2:$C$97619=C8), --(DataSpieler!$H$2:$H$97619="x"), --ISNUMBER(MATCH(DataSpieler!$A$2:$A$97619,_xlfn.ANCHORARRAY($A$2),0)) )} | J8: {=IFERROR( AVERAGE( _xlfn._xlws.FILTER( DataSpieler!$E$2:$E$97619, (DataSpieler!$C$2:$C$97619=C8) * ISNUMBER(MATCH(DataSpieler!$A$2:$A$97619,_xlfn.ANCHORARRAY($A$2),0)) ) ), "" )} | L8: Rivals | M8: {=IFERROR(RIGHT(LOOKUP( 2, 1/(DataSpiele!B:B=Dashboard!L8), DataSpiele!A:A ),3),"000")}
C9: Mariona | E9: {=SUMPRODUCT( --(DataSpieler!$C$2:$C$97619=$C9), --(DataSpieler!$E$2:$E$97619>0), --ISNUMBER(MATCH(DataSpieler!$A$2:$A$97619,_xlfn.ANCHORARRAY($A$2),0)) )} | F9: {=SUMPRODUCT( DataSpieler!$F$2:$F$97619, --(DataSpieler!$C$2:$C$97619=C9), --ISNUMBER(MATCH(DataSpieler!$A$2:$A$97619,_xlfn.ANCHORARRAY($A$2),0)) )} | G9: {=SUMPRODUCT( DataSpieler!$G$2:$G$97619, --(DataSpieler!$C$2:$C$97619=C9), --ISNUMBER(MATCH(DataSpieler!$A$2:$A$97619,_xlfn.ANCHORARRAY($A$2),0)) )} | H9: =F9+G9 | I9: {=SUMPRODUCT( --(DataSpieler!$C$2:$C$97619=C9), --(DataSpieler!$H$2:$H$97619="x"), --ISNUMBER(MATCH(DataSpieler!$A$2:$A$97619,_xlfn.ANCHORARRAY($A$2),0)) )} | J9: {=IFERROR( AVERAGE( _xlfn._xlws.FILTER( DataSpieler!$E$2:$E$97619, (DataSpieler!$C$2:$C$97619=C9) * ISNUMBER(MATCH(DataSpieler!$A$2:$A$97619,_xlfn.ANCHORARRAY($A$2),0)) ) ), "" )} | L9: Champions | M9: {=IFERROR(RIGHT(LOOKUP( 2, 1/(DataSpiele!B:B=Dashboard!L9), DataSpiele!A:A ),3),"000")}
C10: S. Bacha | E10: {=SUMPRODUCT( --(DataSpieler!$C$2:$C$97619=$C10), --(DataSpieler!$E$2:$E$97619>0), --ISNUMBER(MATCH(DataSpieler!$A$2:$A$97619,_xlfn.ANCHORARRAY($A$2),0)) )} | F10: {=SUMPRODUCT( DataSpieler!$F$2:$F$97619, --(DataSpieler!$C$2:$C$97619=C10), --ISNUMBER(MATCH(DataSpieler!$A$2:$A$97619,_xlfn.ANCHORARRAY($A$2),0)) )} | G10: {=SUMPRODUCT( DataSpieler!$G$2:$G$97619, --(DataSpieler!$C$2:$C$97619=C10), --ISNUMBER(MATCH(DataSpieler!$A$2:$A$97619,_xlfn.ANCHORARRAY($A$2),0)) )} | H10: =F10+G10 | I10: {=SUMPRODUCT( --(DataSpieler!$C$2:$C$97619=C10), --(DataSpieler!$H$2:$H$97619="x"), --ISNUMBER(MATCH(DataSpieler!$A$2:$A$97619,_xlfn.ANCHORARRAY($A$2),0)) )} | J10: {=IFERROR( AVERAGE( _xlfn._xlws.FILTER( DataSpieler!$E$2:$E$97619, (DataSpieler!$C$2:$C$97619=C10) * ISNUMBER(MATCH(DataSpieler!$A$2:$A$97619,_xlfn.ANCHORARRAY($A$2),0)) ) ), "" )} | L10: Live Event | M10: {=IFERROR( RIGHT( LOOKUP( 2, 1/(DataSpiele!B:B=Dashboard!L10), DataSpiele!A:A ), 3 ), "000" )}
C11: M. Bright | E11: {=SUMPRODUCT( --(DataSpieler!$C$2:$C$97619=$C11), --(DataSpieler!$E$2:$E$97619>0), --ISNUMBER(MATCH(DataSpieler!$A$2:$A$97619,_xlfn.ANCHORARRAY($A$2),0)) )} | F11: {=SUMPRODUCT( DataSpieler!$F$2:$F$97619, --(DataSpieler!$C$2:$C$97619=C11), --ISNUMBER(MATCH(DataSpieler!$A$2:$A$97619,_xlfn.ANCHORARRAY($A$2),0)) )} | G11: {=SUMPRODUCT( DataSpieler!$G$2:$G$97619, --(DataSpieler!$C$2:$C$97619=C11), --ISNUMBER(MATCH(DataSpieler!$A$2:$A$97619,_xlfn.ANCHORARRAY($A$2),0)) )} | H11: =F11+G11 | I11: {=SUMPRODUCT( --(DataSpieler!$C$2:$C$97619=C11), --(DataSpieler!$H$2:$H$97619="x"), --ISNUMBER(MATCH(DataSpieler!$A$2:$A$97619,_xlfn.ANCHORARRAY($A$2),0)) )} | J11: {=IFERROR( AVERAGE( _xlfn._xlws.FILTER( DataSpieler!$E$2:$E$97619, (DataSpieler!$C$2:$C$97619=C11) * ISNUMBER(MATCH(DataSpieler!$A$2:$A$97619,_xlfn.ANCHORARRAY($A$2),0)) ) ), "" )}
C12: M. van de Ven | E12: {=SUMPRODUCT( --(DataSpieler!$C$2:$C$97619=$C12), --(DataSpieler!$E$2:$E$97619>0), --ISNUMBER(MATCH(DataSpieler!$A$2:$A$97619,_xlfn.ANCHORARRAY($A$2),0)) )} | F12: {=SUMPRODUCT( DataSpieler!$F$2:$F$97619, --(DataSpieler!$C$2:$C$97619=C12), --ISNUMBER(MATCH(DataSpieler!$A$2:$A$97619,_xlfn.ANCHORARRAY($A$2),0)) )} | G12: {=SUMPRODUCT( DataSpieler!$G$2:$G$97619, --(DataSpieler!$C$2:$C$97619=C12), --ISNUMBER(MATCH(DataSpieler!$A$2:$A$97619,_xlfn.ANCHORARRAY($A$2),0)) )} | H12: =F12+G12 | I12: {=SUMPRODUCT( --(DataSpieler!$C$2:$C$97619=C12), --(DataSpieler!$H$2:$H$97619="x"), --ISNUMBER(MATCH(DataSpieler!$A$2:$A$97619,_xlfn.ANCHORARRAY($A$2),0)) )} | J12: {=IFERROR( AVERAGE( _xlfn._xlws.FILTER( DataSpieler!$E$2:$E$97619, (DataSpieler!$C$2:$C$97619=C12) * ISNUMBER(MATCH(DataSpieler!$A$2:$A$97619,_xlfn.ANCHORARRAY($A$2),0)) ) ), "" )} | L12: Matches | M12: Spiel ID | N12: Ergebnis | O12: Streak | P12: Spielstand
C13: Carlos Alberto | E13: {=SUMPRODUCT( --(DataSpieler!$C$2:$C$97619=$C13), --(DataSpieler!$E$2:$E$97619>0), --ISNUMBER(MATCH(DataSpieler!$A$2:$A$97619,_xlfn.ANCHORARRAY($A$2),0)) )} | F13: {=SUMPRODUCT( DataSpieler!$F$2:$F$97619, --(DataSpieler!$C$2:$C$97619=C13), --ISNUMBER(MATCH(DataSpieler!$A$2:$A$97619,_xlfn.ANCHORARRAY($A$2),0)) )} | G13: {=SUMPRODUCT( DataSpieler!$G$2:$G$97619, --(DataSpieler!$C$2:$C$97619=C13), --ISNUMBER(MATCH(DataSpieler!$A$2:$A$97619,_xlfn.ANCHORARRAY($A$2),0)) )} | H13: =F13+G13 | I13: {=SUMPRODUCT( --(DataSpieler!$C$2:$C$97619=C13), --(DataSpieler!$H$2:$H$97619="x"), --ISNUMBER(MATCH(DataSpieler!$A$2:$A$97619,_xlfn.ANCHORARRAY($A$2),0)) )} | J13: {=IFERROR( AVERAGE( _xlfn._xlws.FILTER( DataSpieler!$E$2:$E$97619, (DataSpieler!$C$2:$C$97619=C13) * ISNUMBER(MATCH(DataSpieler!$A$2:$A$97619,_xlfn.ANCHORARRAY($A$2),0)) ) ), "" )} | L13: 1 | M13: {=IFERROR( _xlfn.LET( _xlpm.IDs,_xlfn.ANCHORARRAY($A$2), _xlpm.CatsAll,_xlfn.XLOOKUP(_xlpm.IDs,DataSpiele!$A$2:$A$99814,DataSpiele!$A$2:$A$99814,""), _xlpm.n,MIN(15,ROWS(_xlpm.CatsAll)), _xlpm.Start,ROWS(_xlpm.CatsAll)-_xlpm.n+1, _xlpm.Cats,INDEX(_xlpm.CatsAll,_xlfn.SEQUENCE(_xlpm.n,1,_xlpm.Start,1)), _xlpm.i,ROW()-ROW($M$13)+1, IF(_xlpm.i>_xlpm.n,"",INDEX(_xlpm.Cats,_xlpm.i)) ), "" )} | N13: =IFERROR(_xlfn.XLOOKUP($M$13,DataSpiele!$A:$A,DataSpiele!$H:$H,""),"") | O13: =IF(OR(N13="Sieg",N13="Niederlage"),1,"") | P13: =IFERROR( _xlfn.LET( _xlpm.id, $M$13, _xlpm.seite, _xlfn.XLOOKUP(_xlpm.id, DataSpiele!$A:$A, DataSpiele!$I:$I), _xlpm.heim, _xlfn.XLOOKUP(_xlpm.id, DataSpiele!$A:$A, DataSpiele!$D:$D), _xlpm.aus, _xlfn.XLOOKUP(_xlpm.id, DataSpiele!$A:$A, DataSpiele!$E:$E), IF(_xlpm.seite="Heim", _xlpm.heim & " : " & _xlpm.aus, _xlpm.aus & " : " & _xlpm.heim) ), "" )
C14: G. Vicario | E14: {=SUMPRODUCT( --(DataSpieler!$C$2:$C$97619=$C14), --(DataSpieler!$E$2:$E$97619>0), --ISNUMBER(MATCH(DataSpieler!$A$2:$A$97619,_xlfn.ANCHORARRAY($A$2),0)) )} | F14: {=SUMPRODUCT( DataSpieler!$F$2:$F$97619, --(DataSpieler!$C$2:$C$97619=C14), --ISNUMBER(MATCH(DataSpieler!$A$2:$A$97619,_xlfn.ANCHORARRAY($A$2),0)) )} | G14: {=SUMPRODUCT( DataSpieler!$G$2:$G$97619, --(DataSpieler!$C$2:$C$97619=C14), --ISNUMBER(MATCH(DataSpieler!$A$2:$A$97619,_xlfn.ANCHORARRAY($A$2),0)) )} | H14: =F14+G14 | I14: {=SUMPRODUCT( --(DataSpieler!$C$2:$C$97619=C14), --(DataSpieler!$H$2:$H$97619="x"), --ISNUMBER(MATCH(DataSpieler!$A$2:$A$97619,_xlfn.ANCHORARRAY($A$2),0)) )} | J14: {=IFERROR( AVERAGE( _xlfn._xlws.FILTER( DataSpieler!$E$2:$E$97619, (DataSpieler!$C$2:$C$97619=C14) * ISNUMBER(MATCH(DataSpieler!$A$2:$A$97619,_xlfn.ANCHORARRAY($A$2),0)) ) ), "" )} | L14: 2 | M14: {=IFERROR( _xlfn.LET( _xlpm.IDs,_xlfn.ANCHORARRAY($A$2), _xlpm.CatsAll,_xlfn.XLOOKUP(_xlpm.IDs,DataSpiele!$A$2:$A$99814,DataSpiele!$A$2:$A$99814,""), _xlpm.n,MIN(15,ROWS(_xlpm.CatsAll)), _xlpm.Start,ROWS(_xlpm.CatsAll)-_xlpm.n+1, _xlpm.Cats,INDEX(_xlpm.CatsAll,_xlfn.SEQUENCE(_xlpm.n,1,_xlpm.Start,1)), _xlpm.i,ROW()-ROW($M$13)+1, IF(_xlpm.i>_xlpm.n,"",INDEX(_xlpm.Cats,_xlpm.i)) ), "" )} | N14: =IFERROR(_xlfn.XLOOKUP($M$14,DataSpiele!$A:$A,DataSpiele!$H:$H,""),"") | O14: =IF(OR(N14="Sieg",N14="Niederlage"),IF(N14=N13,O13+1,1),"") | P14: =IFERROR( _xlfn.LET( _xlpm.id, $M$14, _xlpm.seite, _xlfn.XLOOKUP(_xlpm.id, DataSpiele!$A:$A, DataSpiele!$I:$I), _xlpm.heim, _xlfn.XLOOKUP(_xlpm.id, DataSpiele!$A:$A, DataSpiele!$D:$D), _xlpm.aus, _xlfn.XLOOKUP(_xlpm.id, DataSpiele!$A:$A, DataSpiele!$E:$E), IF(_xlpm.seite="Heim", _xlpm.heim & " : " & _xlpm.aus, _xlpm.aus & " : " & _xlpm.heim) ), "" )
C15: Bench | E15: Games | F15: Goals | G15: Assists | H15: Contributions | I15: MOTM | J15: Avg. Rating | L15: 3 | M15: {=IFERROR( _xlfn.LET( _xlpm.IDs,_xlfn.ANCHORARRAY($A$2), _xlpm.CatsAll,_xlfn.XLOOKUP(_xlpm.IDs,DataSpiele!$A$2:$A$99814,DataSpiele!$A$2:$A$99814,""), _xlpm.n,MIN(15,ROWS(_xlpm.CatsAll)), _xlpm.Start,ROWS(_xlpm.CatsAll)-_xlpm.n+1, _xlpm.Cats,INDEX(_xlpm.CatsAll,_xlfn.SEQUENCE(_xlpm.n,1,_xlpm.Start,1)), _xlpm.i,ROW()-ROW($M$13)+1, IF(_xlpm.i>_xlpm.n,"",INDEX(_xlpm.Cats,_xlpm.i)) ), "" )} | N15: =IFERROR(_xlfn.XLOOKUP($M$15,DataSpiele!$A:$A,DataSpiele!$H:$H,""),"") | O15: =IF(OR(N15="Sieg",N15="Niederlage"),IF(N15=N14,O14+1,1),"") | P15: =IFERROR( _xlfn.LET( _xlpm.id, $M$15, _xlpm.seite, _xlfn.XLOOKUP(_xlpm.id, DataSpiele!$A:$A, DataSpiele!$I:$I), _xlpm.heim, _xlfn.XLOOKUP(_xlpm.id, DataSpiele!$A:$A, DataSpiele!$D:$D), _xlpm.aus, _xlfn.XLOOKUP(_xlpm.id, DataSpiele!$A:$A, DataSpiele!$E:$E), IF(_xlpm.seite="Heim", _xlpm.heim & " : " & _xlpm.aus, _xlpm.aus & " : " & _xlpm.heim) ), "" )
C16: Ronaldo | E16: {=SUMPRODUCT( --(DataSpieler!$C$2:$C$97619=$C16), --(DataSpieler!$E$2:$E$97619>0), --ISNUMBER(MATCH(DataSpieler!$A$2:$A$97619,_xlfn.ANCHORARRAY($A$2),0)) )} | F16: {=SUMPRODUCT( DataSpieler!$F$2:$F$97619, --(DataSpieler!$C$2:$C$97619=C16), --ISNUMBER(MATCH(DataSpieler!$A$2:$A$97619,_xlfn.ANCHORARRAY($A$2),0)) )} | G16: {=SUMPRODUCT( DataSpieler!$G$2:$G$97619, --(DataSpieler!$C$2:$C$97619=C16), --ISNUMBER(MATCH(DataSpieler!$A$2:$A$97619,_xlfn.ANCHORARRAY($A$2),0)) )} | H16: =F16+G16 | I16: {=SUMPRODUCT( --(DataSpieler!$C$2:$C$97619=C16), --(DataSpieler!$H$2:$H$97619="x"), --ISNUMBER(MATCH(DataSpieler!$A$2:$A$97619,_xlfn.ANCHORARRAY($A$2),0)) )} | J16: {=IFERROR( AVERAGE( _xlfn._xlws.FILTER( DataSpieler!$E$2:$E$97619, (DataSpieler!$C$2:$C$97619=C16) * ISNUMBER(MATCH(DataSpieler!$A$2:$A$97619,_xlfn.ANCHORARRAY($A$2),0)) ) ), "" )} | L16: 4 | M16: {=IFERROR( _xlfn.LET( _xlpm.IDs,_xlfn.ANCHORARRAY($A$2), _xlpm.CatsAll,_xlfn.XLOOKUP(_xlpm.IDs,DataSpiele!$A$2:$A$99814,DataSpiele!$A$2:$A$99814,""), _xlpm.n,MIN(15,ROWS(_xlpm.CatsAll)), _xlpm.Start,ROWS(_xlpm.CatsAll)-_xlpm.n+1, _xlpm.Cats,INDEX(_xlpm.CatsAll,_xlfn.SEQUENCE(_xlpm.n,1,_xlpm.Start,1)), _xlpm.i,ROW()-ROW($M$13)+1, IF(_xlpm.i>_xlpm.n,"",INDEX(_xlpm.Cats,_xlpm.i)) ), "" )} | N16: =IFERROR(_xlfn.XLOOKUP($M$16,DataSpiele!$A:$A,DataSpiele!$H:$H,""),"") | O16: =IF(OR(N16="Sieg",N16="Niederlage"),IF(N16=N15,O15+1,1),"") | P16: =IFERROR( _xlfn.LET( _xlpm.id, $M16, _xlpm.seite, _xlfn.XLOOKUP(_xlpm.id, DataSpiele!$A:$A, DataSpiele!$I:$I), _xlpm.heim, _xlfn.XLOOKUP(_xlpm.id, DataSpiele!$A:$A, DataSpiele!$D:$D), _xlpm.aus, _xlfn.XLOOKUP(_xlpm.id, DataSpiele!$A:$A, DataSpiele!$E:$E), IF(_xlpm.seite="Heim", _xlpm.heim & " : " & _xlpm.aus, _xlpm.aus & " : " & _xlpm.heim) ), "" )
C17: J. Zanetti | E17: {=SUMPRODUCT( --(DataSpieler!$C$2:$C$97619=$C17), --(DataSpieler!$E$2:$E$97619>0), --ISNUMBER(MATCH(DataSpieler!$A$2:$A$97619,_xlfn.ANCHORARRAY($A$2),0)) )} | F17: {=SUMPRODUCT( DataSpieler!$F$2:$F$97619, --(DataSpieler!$C$2:$C$97619=C17), --ISNUMBER(MATCH(DataSpieler!$A$2:$A$97619,_xlfn.ANCHORARRAY($A$2),0)) )} | G17: {=SUMPRODUCT( DataSpieler!$G$2:$G$97619, --(DataSpieler!$C$2:$C$97619=C17), --ISNUMBER(MATCH(DataSpieler!$A$2:$A$97619,_xlfn.ANCHORARRAY($A$2),0)) )} | H17: =F17+G17 | I17: {=SUMPRODUCT( --(DataSpieler!$C$2:$C$97619=C17), --(DataSpieler!$H$2:$H$97619="x"), --ISNUMBER(MATCH(DataSpieler!$A$2:$A$97619,_xlfn.ANCHORARRAY($A$2),0)) )} | J17: {=IFERROR( AVERAGE( _xlfn._xlws.FILTER( DataSpieler!$E$2:$E$97619, (DataSpieler!$C$2:$C$97619=C17) * ISNUMBER(MATCH(DataSpieler!$A$2:$A$97619,_xlfn.ANCHORARRAY($A$2),0)) ) ), "" )} | L17: 5 | M17: {=IFERROR( _xlfn.LET( _xlpm.IDs,_xlfn.ANCHORARRAY($A$2), _xlpm.CatsAll,_xlfn.XLOOKUP(_xlpm.IDs,DataSpiele!$A$2:$A$99814,DataSpiele!$A$2:$A$99814,""), _xlpm.n,MIN(15,ROWS(_xlpm.CatsAll)), _xlpm.Start,ROWS(_xlpm.CatsAll)-_xlpm.n+1, _xlpm.Cats,INDEX(_xlpm.CatsAll,_xlfn.SEQUENCE(_xlpm.n,1,_xlpm.Start,1)), _xlpm.i,ROW()-ROW($M$13)+1, IF(_xlpm.i>_xlpm.n,"",INDEX(_xlpm.Cats,_xlpm.i)) ), "" )} | N17: =IFERROR(_xlfn.XLOOKUP($M$17,DataSpiele!$A:$A,DataSpiele!$H:$H,""),"") | O17: =IF(OR(N17="Sieg",N17="Niederlage"),IF(N17=N16,O16+1,1),"") | P17: =IFERROR( _xlfn.LET( _xlpm.id, $M17, _xlpm.seite, _xlfn.XLOOKUP(_xlpm.id, DataSpiele!$A:$A, DataSpiele!$I:$I), _xlpm.heim, _xlfn.XLOOKUP(_xlpm.id, DataSpiele!$A:$A, DataSpiele!$D:$D), _xlpm.aus, _xlfn.XLOOKUP(_xlpm.id, DataSpiele!$A:$A, DataSpiele!$E:$E), IF(_xlpm.seite="Heim", _xlpm.heim & " : " & _xlpm.aus, _xlpm.aus & " : " & _xlpm.heim) ), "" )
C18: O. Battle | E18: {=SUMPRODUCT( --(DataSpieler!$C$2:$C$97619=$C18), --(DataSpieler!$E$2:$E$97619>0), --ISNUMBER(MATCH(DataSpieler!$A$2:$A$97619,_xlfn.ANCHORARRAY($A$2),0)) )} | F18: {=SUMPRODUCT( DataSpieler!$F$2:$F$97619, --(DataSpieler!$C$2:$C$97619=C18), --ISNUMBER(MATCH(DataSpieler!$A$2:$A$97619,_xlfn.ANCHORARRAY($A$2),0)) )} | G18: {=SUMPRODUCT( DataSpieler!$G$2:$G$97619, --(DataSpieler!$C$2:$C$97619=C18), --ISNUMBER(MATCH(DataSpieler!$A$2:$A$97619,_xlfn.ANCHORARRAY($A$2),0)) )} | H18: =F18+G18 | I18: {=SUMPRODUCT( --(DataSpieler!$C$2:$C$97619=C18), --(DataSpieler!$H$2:$H$97619="x"), --ISNUMBER(MATCH(DataSpieler!$A$2:$A$97619,_xlfn.ANCHORARRAY($A$2),0)) )} | J18: {=IFERROR( AVERAGE( _xlfn._xlws.FILTER( DataSpieler!$E$2:$E$97619, (DataSpieler!$C$2:$C$97619=C18) * ISNUMBER(MATCH(DataSpieler!$A$2:$A$97619,_xlfn.ANCHORARRAY($A$2),0)) ) ), "" )} | L18: 6 | M18: {=IFERROR( _xlfn.LET( _xlpm.IDs,_xlfn.ANCHORARRAY($A$2), _xlpm.CatsAll,_xlfn.XLOOKUP(_xlpm.IDs,DataSpiele!$A$2:$A$99814,DataSpiele!$A$2:$A$99814,""), _xlpm.n,MIN(15,ROWS(_xlpm.CatsAll)), _xlpm.Start,ROWS(_xlpm.CatsAll)-_xlpm.n+1, _xlpm.Cats,INDEX(_xlpm.CatsAll,_xlfn.SEQUENCE(_xlpm.n,1,_xlpm.Start,1)), _xlpm.i,ROW()-ROW($M$13)+1, IF(_xlpm.i>_xlpm.n,"",INDEX(_xlpm.Cats,_xlpm.i)) ), "" )} | N18: =IFERROR(_xlfn.XLOOKUP($M$18,DataSpiele!$A:$A,DataSpiele!$H:$H,""),"") | O18: =IF(OR(N18="Sieg",N18="Niederlage"),IF(N18=N17,O17+1,1),"") | P18: =IFERROR( _xlfn.LET( _xlpm.id, $M18, _xlpm.seite, _xlfn.XLOOKUP(_xlpm.id, DataSpiele!$A:$A, DataSpiele!$I:$I), _xlpm.heim, _xlfn.XLOOKUP(_xlpm.id, DataSpiele!$A:$A, DataSpiele!$D:$D), _xlpm.aus, _xlfn.XLOOKUP(_xlpm.id, DataSpiele!$A:$A, DataSpiele!$E:$E), IF(_xlpm.seite="Heim", _xlpm.heim & " : " & _xlpm.aus, _xlpm.aus & " : " & _xlpm.heim) ), "" )
C19: M. Salah | E19: {=SUMPRODUCT( --(DataSpieler!$C$2:$C$97619=$C19), --(DataSpieler!$E$2:$E$97619>0), --ISNUMBER(MATCH(DataSpieler!$A$2:$A$97619,_xlfn.ANCHORARRAY($A$2),0)) )} | F19: {=SUMPRODUCT( DataSpieler!$F$2:$F$97619, --(DataSpieler!$C$2:$C$97619=C19), --ISNUMBER(MATCH(DataSpieler!$A$2:$A$97619,_xlfn.ANCHORARRAY($A$2),0)) )} | G19: {=SUMPRODUCT( DataSpieler!$G$2:$G$97619, --(DataSpieler!$C$2:$C$97619=C19), --ISNUMBER(MATCH(DataSpieler!$A$2:$A$97619,_xlfn.ANCHORARRAY($A$2),0)) )} | H19: =F19+G19 | I19: {=SUMPRODUCT( --(DataSpieler!$C$2:$C$97619=C19), --(DataSpieler!$H$2:$H$97619="x"), --ISNUMBER(MATCH(DataSpieler!$A$2:$A$97619,_xlfn.ANCHORARRAY($A$2),0)) )} | J19: {=IFERROR( AVERAGE( _xlfn._xlws.FILTER( DataSpieler!$E$2:$E$97619, (DataSpieler!$C$2:$C$97619=C19) * ISNUMBER(MATCH(DataSpieler!$A$2:$A$97619,_xlfn.ANCHORARRAY($A$2),0)) ) ), "" )} | L19: 7 | M19: {=IFERROR( _xlfn.LET( _xlpm.IDs,_xlfn.ANCHORARRAY($A$2), _xlpm.CatsAll,_xlfn.XLOOKUP(_xlpm.IDs,DataSpiele!$A$2:$A$99814,DataSpiele!$A$2:$A$99814,""), _xlpm.n,MIN(15,ROWS(_xlpm.CatsAll)), _xlpm.Start,ROWS(_xlpm.CatsAll)-_xlpm.n+1, _xlpm.Cats,INDEX(_xlpm.CatsAll,_xlfn.SEQUENCE(_xlpm.n,1,_xlpm.Start,1)), _xlpm.i,ROW()-ROW($M$13)+1, IF(_xlpm.i>_xlpm.n,"",INDEX(_xlpm.Cats,_xlpm.i)) ), "" )} | N19: =IFERROR(_xlfn.XLOOKUP($M$19,DataSpiele!$A:$A,DataSpiele!$H:$H,""),"") | O19: =IF(OR(N19="Sieg",N19="Niederlage"),IF(N19=N18,O18+1,1),"") | P19: =IFERROR( _xlfn.LET( _xlpm.id, $M19, _xlpm.seite, _xlfn.XLOOKUP(_xlpm.id, DataSpiele!$A:$A, DataSpiele!$I:$I), _xlpm.heim, _xlfn.XLOOKUP(_xlpm.id, DataSpiele!$A:$A, DataSpiele!$D:$D), _xlpm.aus, _xlfn.XLOOKUP(_xlpm.id, DataSpiele!$A:$A, DataSpiele!$E:$E), IF(_xlpm.seite="Heim", _xlpm.heim & " : " & _xlpm.aus, _xlpm.aus & " : " & _xlpm.heim) ), "" )
C20: G. Chiellini | E20: {=SUMPRODUCT( --(DataSpieler!$C$2:$C$97619=$C20), --(DataSpieler!$E$2:$E$97619>0), --ISNUMBER(MATCH(DataSpieler!$A$2:$A$97619,_xlfn.ANCHORARRAY($A$2),0)) )} | F20: {=SUMPRODUCT( DataSpieler!$F$2:$F$97619, --(DataSpieler!$C$2:$C$97619=C20), --ISNUMBER(MATCH(DataSpieler!$A$2:$A$97619,_xlfn.ANCHORARRAY($A$2),0)) )} | G20: {=SUMPRODUCT( DataSpieler!$G$2:$G$97619, --(DataSpieler!$C$2:$C$97619=C20), --ISNUMBER(MATCH(DataSpieler!$A$2:$A$97619,_xlfn.ANCHORARRAY($A$2),0)) )} | H20: =F20+G20 | I20: {=SUMPRODUCT( --(DataSpieler!$C$2:$C$97619=C20), --(DataSpieler!$H$2:$H$97619="x"), --ISNUMBER(MATCH(DataSpieler!$A$2:$A$97619,_xlfn.ANCHORARRAY($A$2),0)) )} | J20: {=IFERROR( AVERAGE( _xlfn._xlws.FILTER( DataSpieler!$E$2:$E$97619, (DataSpieler!$C$2:$C$97619=C20) * ISNUMBER(MATCH(DataSpieler!$A$2:$A$97619,_xlfn.ANCHORARRAY($A$2),0)) ) ), "" )} | L20: 8 | M20: {=IFERROR( _xlfn.LET( _xlpm.IDs,_xlfn.ANCHORARRAY($A$2), _xlpm.CatsAll,_xlfn.XLOOKUP(_xlpm.IDs,DataSpiele!$A$2:$A$99814,DataSpiele!$A$2:$A$99814,""), _xlpm.n,MIN(15,ROWS(_xlpm.CatsAll)), _xlpm.Start,ROWS(_xlpm.CatsAll)-_xlpm.n+1, _xlpm.Cats,INDEX(_xlpm.CatsAll,_xlfn.SEQUENCE(_xlpm.n,1,_xlpm.Start,1)), _xlpm.i,ROW()-ROW($M$13)+1, IF(_xlpm.i>_xlpm.n,"",INDEX(_xlpm.Cats,_xlpm.i)) ), "" )} | N20: =IFERROR(_xlfn.XLOOKUP($M$20,DataSpiele!$A:$A,DataSpiele!$H:$H,""),"") | O20: =IF(OR(N20="Sieg",N20="Niederlage"),IF(N20=N19,O19+1,1),"") | P20: =IFERROR( _xlfn.LET( _xlpm.id, $M20, _xlpm.seite, _xlfn.XLOOKUP(_xlpm.id, DataSpiele!$A:$A, DataSpiele!$I:$I), _xlpm.heim, _xlfn.XLOOKUP(_xlpm.id, DataSpiele!$A:$A, DataSpiele!$D:$D), _xlpm.aus, _xlfn.XLOOKUP(_xlpm.id, DataSpiele!$A:$A, DataSpiele!$E:$E), IF(_xlpm.seite="Heim", _xlpm.heim & " : " & _xlpm.aus, _xlpm.aus & " : " & _xlpm.heim) ), "" )
C21: S. Doumbia | E21: {=SUMPRODUCT( --(DataSpieler!$C$2:$C$97619=$C21), --(DataSpieler!$E$2:$E$97619>0), --ISNUMBER(MATCH(DataSpieler!$A$2:$A$97619,_xlfn.ANCHORARRAY($A$2),0)) )} | F21: {=SUMPRODUCT( DataSpieler!$F$2:$F$97619, --(DataSpieler!$C$2:$C$97619=C21), --ISNUMBER(MATCH(DataSpieler!$A$2:$A$97619,_xlfn.ANCHORARRAY($A$2),0)) )} | G21: {=SUMPRODUCT( DataSpieler!$G$2:$G$97619, --(DataSpieler!$C$2:$C$97619=C21), --ISNUMBER(MATCH(DataSpieler!$A$2:$A$97619,_xlfn.ANCHORARRAY($A$2),0)) )} | H21: =F21+G21 | I21: {=SUMPRODUCT( --(DataSpieler!$C$2:$C$97619=C21), --(DataSpieler!$H$2:$H$97619="x"), --ISNUMBER(MATCH(DataSpieler!$A$2:$A$97619,_xlfn.ANCHORARRAY($A$2),0)) )} | J21: {=IFERROR( AVERAGE( _xlfn._xlws.FILTER( DataSpieler!$E$2:$E$97619, (DataSpieler!$C$2:$C$97619=C21) * ISNUMBER(MATCH(DataSpieler!$A$2:$A$97619,_xlfn.ANCHORARRAY($A$2),0)) ) ), "" )} | L21: 9 | M21: {=IFERROR( _xlfn.LET( _xlpm.IDs,_xlfn.ANCHORARRAY($A$2), _xlpm.CatsAll,_xlfn.XLOOKUP(_xlpm.IDs,DataSpiele!$A$2:$A$99814,DataSpiele!$A$2:$A$99814,""), _xlpm.n,MIN(15,ROWS(_xlpm.CatsAll)), _xlpm.Start,ROWS(_xlpm.CatsAll)-_xlpm.n+1, _xlpm.Cats,INDEX(_xlpm.CatsAll,_xlfn.SEQUENCE(_xlpm.n,1,_xlpm.Start,1)), _xlpm.i,ROW()-ROW($M$13)+1, IF(_xlpm.i>_xlpm.n,"",INDEX(_xlpm.Cats,_xlpm.i)) ), "" )} | N21: =IFERROR(_xlfn.XLOOKUP($M$21,DataSpiele!$A:$A,DataSpiele!$H:$H,""),"") | O21: =IF(OR(N21="Sieg",N21="Niederlage"),IF(N21=N20,O20+1,1),"") | P21: =IFERROR( _xlfn.LET( _xlpm.id, $M21, _xlpm.seite, _xlfn.XLOOKUP(_xlpm.id, DataSpiele!$A:$A, DataSpiele!$I:$I), _xlpm.heim, _xlfn.XLOOKUP(_xlpm.id, DataSpiele!$A:$A, DataSpiele!$D:$D), _xlpm.aus, _xlfn.XLOOKUP(_xlpm.id, DataSpiele!$A:$A, DataSpiele!$E:$E), IF(_xlpm.seite="Heim", _xlpm.heim & " : " & _xlpm.aus, _xlpm.aus & " : " & _xlpm.heim) ), "" )
C22: T. Bischof | E22: {=SUMPRODUCT( --(DataSpieler!$C$2:$C$97619=$C22), --(DataSpieler!$E$2:$E$97619>0), --ISNUMBER(MATCH(DataSpieler!$A$2:$A$97619,_xlfn.ANCHORARRAY($A$2),0)) )} | F22: {=SUMPRODUCT( DataSpieler!$F$2:$F$97619, --(DataSpieler!$C$2:$C$97619=C22), --ISNUMBER(MATCH(DataSpieler!$A$2:$A$97619,_xlfn.ANCHORARRAY($A$2),0)) )} | G22: {=SUMPRODUCT( DataSpieler!$G$2:$G$97619, --(DataSpieler!$C$2:$C$97619=C22), --ISNUMBER(MATCH(DataSpieler!$A$2:$A$97619,_xlfn.ANCHORARRAY($A$2),0)) )} | H22: =F22+G22 | I22: {=SUMPRODUCT( --(DataSpieler!$C$2:$C$97619=C22), --(DataSpieler!$H$2:$H$97619="x"), --ISNUMBER(MATCH(DataSpieler!$A$2:$A$97619,_xlfn.ANCHORARRAY($A$2),0)) )} | J22: {=IFERROR( AVERAGE( _xlfn._xlws.FILTER( DataSpieler!$E$2:$E$97619, (DataSpieler!$C$2:$C$97619=C22) * ISNUMBER(MATCH(DataSpieler!$A$2:$A$97619,_xlfn.ANCHORARRAY($A$2),0)) ) ), "" )} | L22: 10 | M22: {=IFERROR( _xlfn.LET( _xlpm.IDs,_xlfn.ANCHORARRAY($A$2), _xlpm.CatsAll,_xlfn.XLOOKUP(_xlpm.IDs,DataSpiele!$A$2:$A$99814,DataSpiele!$A$2:$A$99814,""), _xlpm.n,MIN(15,ROWS(_xlpm.CatsAll)), _xlpm.Start,ROWS(_xlpm.CatsAll)-_xlpm.n+1, _xlpm.Cats,INDEX(_xlpm.CatsAll,_xlfn.SEQUENCE(_xlpm.n,1,_xlpm.Start,1)), _xlpm.i,ROW()-ROW($M$13)+1, IF(_xlpm.i>_xlpm.n,"",INDEX(_xlpm.Cats,_xlpm.i)) ), "" )} | N22: =IFERROR(_xlfn.XLOOKUP($M$22,DataSpiele!$A:$A,DataSpiele!$H:$H,""),"") | O22: =IF(OR(N22="Sieg",N22="Niederlage"),IF(N22=N21,O21+1,1),"") | P22: =IFERROR( _xlfn.LET( _xlpm.id, $M22, _xlpm.seite, _xlfn.XLOOKUP(_xlpm.id, DataSpiele!$A:$A, DataSpiele!$I:$I), _xlpm.heim, _xlfn.XLOOKUP(_xlpm.id, DataSpiele!$A:$A, DataSpiele!$D:$D), _xlpm.aus, _xlfn.XLOOKUP(_xlpm.id, DataSpiele!$A:$A, DataSpiele!$E:$E), IF(_xlpm.seite="Heim", _xlpm.heim & " : " & _xlpm.aus, _xlpm.aus & " : " & _xlpm.heim) ), "" )
C23: Legacy | E23: Games | F23: Goals | G23: Assists | H23: Contributions | I23: MOTM | J23: Avg. Rating | L23: 11 | M23: {=IFERROR( _xlfn.LET( _xlpm.IDs,_xlfn.ANCHORARRAY($A$2), _xlpm.CatsAll,_xlfn.XLOOKUP(_xlpm.IDs,DataSpiele!$A$2:$A$99814,DataSpiele!$A$2:$A$99814,""), _xlpm.n,MIN(15,ROWS(_xlpm.CatsAll)), _xlpm.Start,ROWS(_xlpm.CatsAll)-_xlpm.n+1, _xlpm.Cats,INDEX(_xlpm.CatsAll,_xlfn.SEQUENCE(_xlpm.n,1,_xlpm.Start,1)), _xlpm.i,ROW()-ROW($M$13)+1, IF(_xlpm.i>_xlpm.n,"",INDEX(_xlpm.Cats,_xlpm.i)) ), "" )} | N23: =IFERROR(_xlfn.XLOOKUP($M$23,DataSpiele!$A:$A,DataSpiele!$H:$H,""),"") | O23: =IF(OR(N23="Sieg",N23="Niederlage"),IF(N23=N22,O22+1,1),"") | P23: =IFERROR( _xlfn.LET( _xlpm.id, $M23, _xlpm.seite, _xlfn.XLOOKUP(_xlpm.id, DataSpiele!$A:$A, DataSpiele!$I:$I), _xlpm.heim, _xlfn.XLOOKUP(_xlpm.id, DataSpiele!$A:$A, DataSpiele!$D:$D), _xlpm.aus, _xlfn.XLOOKUP(_xlpm.id, DataSpiele!$A:$A, DataSpiele!$E:$E), IF(_xlpm.seite="Heim", _xlpm.heim & " : " & _xlpm.aus, _xlpm.aus & " : " & _xlpm.heim) ), "" )
C24: T. Courtois | E24: {=SUMPRODUCT( --(DataSpieler!$C$2:$C$97619=$C24), --(DataSpieler!$E$2:$E$97619>0), --ISNUMBER(MATCH(DataSpieler!$A$2:$A$97619,_xlfn.ANCHORARRAY($A$2),0)) )} | F24: {=SUMPRODUCT( DataSpieler!$F$2:$F$97619, --(DataSpieler!$C$2:$C$97619=C24), --ISNUMBER(MATCH(DataSpieler!$A$2:$A$97619,_xlfn.ANCHORARRAY($A$2),0)) )} | G24: {=SUMPRODUCT( DataSpieler!$G$2:$G$97619, --(DataSpieler!$C$2:$C$97619=C24), --ISNUMBER(MATCH(DataSpieler!$A$2:$A$97619,_xlfn.ANCHORARRAY($A$2),0)) )} | H24: =F24+G24 | I24: {=SUMPRODUCT( --(DataSpieler!$C$2:$C$97619=C24), --(DataSpieler!$H$2:$H$97619="x"), --ISNUMBER(MATCH(DataSpieler!$A$2:$A$97619,_xlfn.ANCHORARRAY($A$2),0)) )} | J24: {=IFERROR( AVERAGE( _xlfn._xlws.FILTER( DataSpieler!$E$2:$E$97619, (DataSpieler!$C$2:$C$97619=C24) * ISNUMBER(MATCH(DataSpieler!$A$2:$A$97619,_xlfn.ANCHORARRAY($A$2),0)) ) ), "" )} | L24: 12 | M24: {=IFERROR( _xlfn.LET( _xlpm.IDs,_xlfn.ANCHORARRAY($A$2), _xlpm.CatsAll,_xlfn.XLOOKUP(_xlpm.IDs,DataSpiele!$A$2:$A$99814,DataSpiele!$A$2:$A$99814,""), _xlpm.n,MIN(15,ROWS(_xlpm.CatsAll)), _xlpm.Start,ROWS(_xlpm.CatsAll)-_xlpm.n+1, _xlpm.Cats,INDEX(_xlpm.CatsAll,_xlfn.SEQUENCE(_xlpm.n,1,_xlpm.Start,1)), _xlpm.i,ROW()-ROW($M$13)+1, IF(_xlpm.i>_xlpm.n,"",INDEX(_xlpm.Cats,_xlpm.i)) ), "" )} | N24: =IFERROR(_xlfn.XLOOKUP($M$24,DataSpiele!$A:$A,DataSpiele!$H:$H,""),"") | O24: =IF(OR(N24="Sieg",N24="Niederlage"),IF(N24=N23,O23+1,1),"") | P24: =IFERROR( _xlfn.LET( _xlpm.id, $M24, _xlpm.seite, _xlfn.XLOOKUP(_xlpm.id, DataSpiele!$A:$A, DataSpiele!$I:$I), _xlpm.heim, _xlfn.XLOOKUP(_xlpm.id, DataSpiele!$A:$A, DataSpiele!$D:$D), _xlpm.aus, _xlfn.XLOOKUP(_xlpm.id, DataSpiele!$A:$A, DataSpiele!$E:$E), IF(_xlpm.seite="Heim", _xlpm.heim & " : " & _xlpm.aus, _xlpm.aus & " : " & _xlpm.heim) ), "" )
C25: M. Desailly | E25: {=SUMPRODUCT( --(DataSpieler!$C$2:$C$97619=$C25), --(DataSpieler!$E$2:$E$97619>0), --ISNUMBER(MATCH(DataSpieler!$A$2:$A$97619,_xlfn.ANCHORARRAY($A$2),0)) )} | F25: {=SUMPRODUCT( DataSpieler!$F$2:$F$97619, --(DataSpieler!$C$2:$C$97619=C25), --ISNUMBER(MATCH(DataSpieler!$A$2:$A$97619,_xlfn.ANCHORARRAY($A$2),0)) )} | G25: {=SUMPRODUCT( DataSpieler!$G$2:$G$97619, --(DataSpieler!$C$2:$C$97619=C25), --ISNUMBER(MATCH(DataSpieler!$A$2:$A$97619,_xlfn.ANCHORARRAY($A$2),0)) )} | H25: =F25+G25 | I25: {=SUMPRODUCT( --(DataSpieler!$C$2:$C$97619=C25), --(DataSpieler!$H$2:$H$97619="x"), --ISNUMBER(MATCH(DataSpieler!$A$2:$A$97619,_xlfn.ANCHORARRAY($A$2),0)) )} | J25: {=IFERROR( AVERAGE( _xlfn._xlws.FILTER( DataSpieler!$E$2:$E$97619, (DataSpieler!$C$2:$C$97619=C25) * ISNUMBER(MATCH(DataSpieler!$A$2:$A$97619,_xlfn.ANCHORARRAY($A$2),0)) ) ), "" )} | L25: 13 | M25: {=IFERROR( _xlfn.LET( _xlpm.IDs,_xlfn.ANCHORARRAY($A$2), _xlpm.CatsAll,_xlfn.XLOOKUP(_xlpm.IDs,DataSpiele!$A$2:$A$99814,DataSpiele!$A$2:$A$99814,""), _xlpm.n,MIN(15,ROWS(_xlpm.CatsAll)), _xlpm.Start,ROWS(_xlpm.CatsAll)-_xlpm.n+1, _xlpm.Cats,INDEX(_xlpm.CatsAll,_xlfn.SEQUENCE(_xlpm.n,1,_xlpm.Start,1)), _xlpm.i,ROW()-ROW($M$13)+1, IF(_xlpm.i>_xlpm.n,"",INDEX(_xlpm.Cats,_xlpm.i)) ), "" )} | N25: =IFERROR(_xlfn.XLOOKUP($M$25,DataSpiele!$A:$A,DataSpiele!$H:$H,""),"") | O25: =IF(OR(N25="Sieg",N25="Niederlage"),IF(N25=N24,O24+1,1),"") | P25: =IFERROR( _xlfn.LET( _xlpm.id, $M25, _xlpm.seite, _xlfn.XLOOKUP(_xlpm.id, DataSpiele!$A:$A, DataSpiele!$I:$I), _xlpm.heim, _xlfn.XLOOKUP(_xlpm.id, DataSpiele!$A:$A, DataSpiele!$D:$D), _xlpm.aus, _xlfn.XLOOKUP(_xlpm.id, DataSpiele!$A:$A, DataSpiele!$E:$E), IF(_xlpm.seite="Heim", _xlpm.heim & " : " & _xlpm.aus, _xlpm.aus & " : " & _xlpm.heim) ), "" )
C26: N. Williams | E26: {=SUMPRODUCT( --(DataSpieler!$C$2:$C$97619=$C26), --(DataSpieler!$E$2:$E$97619>0), --ISNUMBER(MATCH(DataSpieler!$A$2:$A$97619,_xlfn.ANCHORARRAY($A$2),0)) )} | F26: {=SUMPRODUCT( DataSpieler!$F$2:$F$97619, --(DataSpieler!$C$2:$C$97619=C26), --ISNUMBER(MATCH(DataSpieler!$A$2:$A$97619,_xlfn.ANCHORARRAY($A$2),0)) )} | G26: {=SUMPRODUCT( DataSpieler!$G$2:$G$97619, --(DataSpieler!$C$2:$C$97619=C26), --ISNUMBER(MATCH(DataSpieler!$A$2:$A$97619,_xlfn.ANCHORARRAY($A$2),0)) )} | H26: =F26+G26 | I26: {=SUMPRODUCT( --(DataSpieler!$C$2:$C$97619=C26), --(DataSpieler!$H$2:$H$97619="x"), --ISNUMBER(MATCH(DataSpieler!$A$2:$A$97619,_xlfn.ANCHORARRAY($A$2),0)) )} | J26: {=IFERROR( AVERAGE( _xlfn._xlws.FILTER( DataSpieler!$E$2:$E$97619, (DataSpieler!$C$2:$C$97619=C26) * ISNUMBER(MATCH(DataSpieler!$A$2:$A$97619,_xlfn.ANCHORARRAY($A$2),0)) ) ), "" )} | L26: 14 | M26: {=IFERROR( _xlfn.LET( _xlpm.IDs,_xlfn.ANCHORARRAY($A$2), _xlpm.CatsAll,_xlfn.XLOOKUP(_xlpm.IDs,DataSpiele!$A$2:$A$99814,DataSpiele!$A$2:$A$99814,""), _xlpm.n,MIN(15,ROWS(_xlpm.CatsAll)), _xlpm.Start,ROWS(_xlpm.CatsAll)-_xlpm.n+1, _xlpm.Cats,INDEX(_xlpm.CatsAll,_xlfn.SEQUENCE(_xlpm.n,1,_xlpm.Start,1)), _xlpm.i,ROW()-ROW($M$13)+1, IF(_xlpm.i>_xlpm.n,"",INDEX(_xlpm.Cats,_xlpm.i)) ), "" )} | N26: =IFERROR(_xlfn.XLOOKUP($M$26,DataSpiele!$A:$A,DataSpiele!$H:$H,""),"") | O26: =IF(OR(N26="Sieg",N26="Niederlage"),IF(N26=N25,O25+1,1),"") | P26: =IFERROR( _xlfn.LET( _xlpm.id, $M26, _xlpm.seite, _xlfn.XLOOKUP(_xlpm.id, DataSpiele!$A:$A, DataSpiele!$I:$I), _xlpm.heim, _xlfn.XLOOKUP(_xlpm.id, DataSpiele!$A:$A, DataSpiele!$D:$D), _xlpm.aus, _xlfn.XLOOKUP(_xlpm.id, DataSpiele!$A:$A, DataSpiele!$E:$E), IF(_xlpm.seite="Heim", _xlpm.heim & " : " & _xlpm.aus, _xlpm.aus & " : " & _xlpm.heim) ), "" )
L27: 15 | M27: {=IFERROR( _xlfn.LET( _xlpm.IDs,_xlfn.ANCHORARRAY($A$2), _xlpm.CatsAll,_xlfn.XLOOKUP(_xlpm.IDs,DataSpiele!$A$2:$A$99814,DataSpiele!$A$2:$A$99814,""), _xlpm.n,MIN(15,ROWS(_xlpm.CatsAll)), _xlpm.Start,ROWS(_xlpm.CatsAll)-_xlpm.n+1, _xlpm.Cats,INDEX(_xlpm.CatsAll,_xlfn.SEQUENCE(_xlpm.n,1,_xlpm.Start,1)), _xlpm.i,ROW()-ROW($M$13)+1, IF(_xlpm.i>_xlpm.n,"",INDEX(_xlpm.Cats,_xlpm.i)) ), "" )} | N27: =IFERROR(_xlfn.XLOOKUP($M$27,DataSpiele!$A:$A,DataSpiele!$H:$H,""),"") | O27: =IF(OR(N27="Sieg",N27="Niederlage"),IF(N27=N26,O26+1,1),"") | P27: =IFERROR( _xlfn.LET( _xlpm.id, $M27, _xlpm.seite, _xlfn.XLOOKUP(_xlpm.id, DataSpiele!$A:$A, DataSpiele!$I:$I), _xlpm.heim, _xlfn.XLOOKUP(_xlpm.id, DataSpiele!$A:$A, DataSpiele!$D:$D), _xlpm.aus, _xlfn.XLOOKUP(_xlpm.id, DataSpiele!$A:$A, DataSpiele!$E:$E), IF(_xlpm.seite="Heim", _xlpm.heim & " : " & _xlpm.aus, _xlpm.aus & " : " & _xlpm.heim) ), "" )
C29: Top Goals | D29: =INDEX(C4:C22,MATCH(D31,F4:F22,0)) | E29: =INDEX(C4:C22,MATCH(E31,F4:F22,0)) | F29: =INDEX(C4:C22,MATCH(F31,F4:F22,0)) | H29: Clean Sheets | I29: Avg. Posession | J29: Home Games | L29: Current Record
L30: Won | M30: Lost | N30: Draw
D31: =LARGE(F1:F21, 1) | E31: =LARGE(F1:F21, 2) | F31: =LARGE(F1:F21, 3) | H31: {=IFERROR(SUM( --( _xlfn.XLOOKUP(_xlfn.ANCHORARRAY( $A$2), DataSpiele!$A$2:$A$99814, DataSpiele!$K$2:$K$99814, "" ) ="ja" ) ),"0")} | I31: {=IFERROR( AVERAGE( _xlfn.XLOOKUP(_xlfn.ANCHORARRAY( $A$2), DataSpiele!$A$2:$A$99814, DataSpiele!$O$2:$O$99814, "" ) ), " " )} | J31: {=IFERROR( _xlfn.LET( _xlpm.IDs,_xlfn.ANCHORARRAY(Dashboard!$A$2), _xlpm.Ort,_xlfn.XLOOKUP(_xlpm.IDs,DataSpiele!$A$2:$A$99839,DataSpiele!$I$2:$I$99839,""), _xlpm.HeimAnz,SUMPRODUCT(--(LEFT(TRIM(_xlpm.Ort),4)="Heim")), _xlpm.HeimAnz/COUNTA(_xlpm.IDs) ), 0 )} | L31: {=IFERROR(SUM( --( _xlfn.XLOOKUP(_xlfn.ANCHORARRAY( $A$2), DataSpiele!$A$2:$A$99814, DataSpiele!$H$2:$H$99814, "" ) ="Sieg" ) ),"0")} | M31: {=IFERROR(SUM( --( _xlfn.XLOOKUP(_xlfn.ANCHORARRAY( $A$2), DataSpiele!$A$2:$A$99814, DataSpiele!$H$2:$H$99814, "" ) ="Niederlage" ) ),"0")} | N31: {=IFERROR(SUM( --( _xlfn.XLOOKUP(_xlfn.ANCHORARRAY( $A$2), DataSpiele!$A$2:$A$99814, DataSpiele!$H$2:$H$99814, "" ) ="Unentschieden" ) ),"0")}
L33: Rage Quit | M33: Rage Quit | N33: by ET
C34: Top Assist | D34: =INDEX(C4:C22,MATCH(D36,G4:G22,0)) | E34: =INDEX(C4:C22,MATCH(E36,G4:G22,0)) | F34: =INDEX(C4:C22,MATCH(F36,G4:G22,0)) | H34: Passing | I34: For | J34: Against | L34: {=IFERROR(SUM( --( _xlfn.XLOOKUP(_xlfn.ANCHORARRAY( $A$2), DataSpiele!$A$2:$A$99814, DataSpiele!$N$2:$N$99814, "" ) ="Gegner hat aufgegeben (Sieg)" ) ),"")} | M34: {=IFERROR(SUM( --( _xlfn.XLOOKUP(_xlfn.ANCHORARRAY( $A$2), DataSpiele!$A$2:$A$99814, DataSpiele!$N$2:$N$99814, "" ) ="Ich habe aufgegeben (Niederlage)" ) ),"")} | N34: {=IFERROR(SUM( --( (_xlfn.XLOOKUP(_xlfn.ANCHORARRAY($A$2),DataSpiele!$A$2:$A$99814,DataSpiele!$M$2:$M$99814,"")="ja") * (_xlfn.XLOOKUP(_xlfn.ANCHORARRAY($A$2),DataSpiele!$A$2:$A$99814,DataSpiele!$H$2:$H$99814,"")="Unentschieden") ) ),"")}
D36: =LARGE($G$3:$G$22, 1) | E36: =LARGE($G$3:$G$22, 2) | F36: =LARGE($G$3:$G$22, 3) | H36: Total per Game | I36: {=IFERROR( AVERAGE( _xlfn.XLOOKUP(_xlfn.ANCHORARRAY( $A$2), DataSpiele!$A$2:$A$99814, DataSpiele!$V$2:$V$99814, "" ) ), " " )} | J36: {=IFERROR( AVERAGE( _xlfn.XLOOKUP(_xlfn.ANCHORARRAY( $A$2), DataSpiele!$A$2:$A$99814, DataSpiele!$W$2:$W$99814, "" ) ), " " )} | L36: by ET | M36: by ET
H37: Pass % | I37: {=IFERROR( AVERAGE( _xlfn.XLOOKUP(_xlfn.ANCHORARRAY( $A$2), DataSpiele!$A$2:$A$99814, DataSpiele!$X$2:$X$99814, "" ) ), " " )} | J37: {=IFERROR( AVERAGE( _xlfn.XLOOKUP(_xlfn.ANCHORARRAY( $A$2), DataSpiele!$A$2:$A$99814, DataSpiele!$Y$2:$Y$99814, "" ) ), " " )} | L37: {=IFERROR(SUM( --( (_xlfn.XLOOKUP(_xlfn.ANCHORARRAY($A$2),DataSpiele!$A$2:$A$99814,DataSpiele!$L$2:$L$99814,"")="ja") * (_xlfn.XLOOKUP(_xlfn.ANCHORARRAY($A$2),DataSpiele!$A$2:$A$99814,DataSpiele!$H$2:$H$99814,"")="Sieg") ) ),"")} | M37: {=IFERROR(SUM( --( (_xlfn.XLOOKUP(_xlfn.ANCHORARRAY($A$2),DataSpiele!$A$2:$A$99814,DataSpiele!$L$2:$L$99814,"")="ja") * (_xlfn.XLOOKUP(_xlfn.ANCHORARRAY($A$2),DataSpiele!$A$2:$A$99814,DataSpiele!$H$2:$H$99814,"")="Niederlage") ) ),"")} | O37: Streak per 15 Matches
O38: Max Win Streak | P38: =_xlfn.MAXIFS(O13:O27,N13:N27,"Sieg")
C39: Best Avg. Rating | D39: =IFERROR(INDEX(C4:C22,MATCH(D41,J4:J22,0)),"") | E39: =IFERROR(INDEX(C4:C22,MATCH(E41,J4:J22,0)),"") | F39: =IFERROR(INDEX(C4:C22,MATCH(F41,J4:J22,0)),"") | H39: Schnitt | I39: For | J39: Against | L39: by PEN | M39: by PEN
L40: {=IFERROR(SUM( --( (_xlfn.XLOOKUP(_xlfn.ANCHORARRAY($A$2),DataSpiele!$A$2:$A$99814,DataSpiele!$M$2:$M$99814,"")="ja") * (_xlfn.XLOOKUP(_xlfn.ANCHORARRAY($A$2),DataSpiele!$A$2:$A$99814,DataSpiele!$H$2:$H$99814,"")="Sieg") ) ),"")} | M40: {=IFERROR(SUM( --( (_xlfn.XLOOKUP(_xlfn.ANCHORARRAY($A$2),DataSpiele!$A$2:$A$99814,DataSpiele!$M$2:$M$99814,"")="ja") * (_xlfn.XLOOKUP(_xlfn.ANCHORARRAY($A$2),DataSpiele!$A$2:$A$99814,DataSpiele!$H$2:$H$99814,"")="Niederlage") ) ),"")} | O40: Max Loss Streak | P40: =_xlfn.MAXIFS(O13:O27,N13:N27,"Niederlage")
D41: =IFERROR(LARGE(J4:J22,1),"") | E41: =IFERROR(LARGE(J4:J22,2),"") | F41: =IFERROR(LARGE(J4:J22,3),"") | H41: Zweikämpfe | I41: {=IFERROR( AVERAGE( _xlfn.XLOOKUP(_xlfn.ANCHORARRAY( $A$2), DataSpiele!$A$2:$A$99814, DataSpiele!$AF$2:$AF$99814, "" ) ), " " )} | J41: {=IFERROR( AVERAGE( _xlfn.XLOOKUP(_xlfn.ANCHORARRAY( $A$2), DataSpiele!$A$2:$A$99814, DataSpiele!$AG$2:$AG$99814, "" ) ), " " )}
H42: davon gewonnen | I42: {=IFERROR( AVERAGE( _xlfn.XLOOKUP(_xlfn.ANCHORARRAY( $A$2), DataSpiele!$A$2:$A$99814, DataSpiele!$AH$2:$AH$99814, "" ) ), " " )} | J42: {=IFERROR( AVERAGE( _xlfn.XLOOKUP(_xlfn.ANCHORARRAY( $A$2), DataSpiele!$A$2:$A$99814, DataSpiele!$AI$2:$AI$99814, "" ) ), " " )}
L43: Goals Difference
...

Sheet DataSpiele
A1: SpielID | B1: Spielkategorie | C1: Datum | D1: HeimT | E1: AuswärtsT | F1: Heim | G1: Auswärts | H1: Ergebnis | I1: Wo | J1: Spieldauer | K1: CleanSheet | L1: Verlängerung | M1: Elfmeterschießen | N1: Abbruchgrund | O1: Ballbesitiz | P1: Schüsse | Q1: SchüsseOpp | R1: Schusspräzision | S1: SchusspräzisionOpp | T1: xGoals | U1: xGoalsOpp | V1: Pässe | W1: PässeOpp | X1: Erfolgreiche Pässe | Y1: Erfolgreiche Pässe Opp | Z1: Erfolgreiche Dribblings | AA1: Erfolgreiche Dribblings Opp | AB1: Gelbe Karten | AC1: Gelbe Karten Opp | AD1: Rote Karten | AE1: Rote Karten Opp | AF1: zweikaempfe | AG1: zweikaempfeOpp | AH1: gew_zweikaempfe | AI1: gew_zweikaempfeOpp | AJ1: abgefangen | AK1: abgefangenOpp | AL1: paraden | AM1: paradenOpp | AN1: fouls | AO1: foulsOpp | AP1: abseits | AQ1: abseitsOpp | AR1: ecken | AS1: eckenOpp | AT1: freistöße | AU1: freistößeOpp | AV1: elfmeter | AW1: elfmeterOpp | AX1: Unsicher/Fehlt
A2: RIV001 | B2: Rivals | C2: 46057 | D2: 10 | E2: 4 | F2: Momentum FC | G2: Luebeck VfB | H2: Sieg | I2: Heim | J2: 3.7986111 | K2: nein | L2: nein | M2: nein | O2: 0.54 | P2: 18 | Q2: 6 | R2: 0.78 | S2: 1 | T2: 7.4 | U2: 1.8 | V2: 190 | W2: 106 | X2: 0.88 | Y2: 0.84 | Z2: 0.95 | AA2: 0.79 | AB2: 0 | AC2: 0 | AD2: 0 | AE2: 0 | AF2: 16 | AG2: 72 | AH2: 13 | AI2: 8 | AJ2: 16 | AK2: 17 | AL2: 2 | AM2: 4 | AN2: 0 | AO2: 0 | AP2: 4 | AQ2: 1 | AR2: 2 | AS2: 2 | AT2: 1 | AU2: 4 | AV2: 0 | AW2: 0

Sheet DataSpieler
A1: SpielID | B1: Spielkategorie | C1: Name | D1: Position | E1: Bewertung | F1: Tore | G1: Vorlagen | H1: MOTM | I1: Kommentar KI
A2: RIV001 | B2: Rivals | C2: A. Russo | D2: ST | E2: 10 | F2: 4 | G2: 1 | H2: x
A3: RIV001 | B3: Rivals | C3: J. Cruyff | D3: ZOM | E3: 6.4 | F3: 0 | G3: 0
A4: RIV001 | B4: Rivals | C4: F. Totti | D4: ZOM | E4: 9.7 | F4: 1 | G4: 6
A5: RIV001 | B5: Rivals | C5: N. Williams | D5: LM | E5: 6.5 | F5: 0 | G5: 0
A6: RIV001 | B6: Rivals | C6: Vini Jr. | D6: LM | E6: 7.8 | F6: 0 | G6: 1
A7: RIV001 | B7: Rivals | C7: J. Irvine | D7: LZM | E7: 8.1 | F7: 0 | G7: 1
A8: RIV001 | B8: Rivals | C8: F. Valverde | D8: RZM | E8: 6.8 | F8: 1 | G8: 0
A9: RIV001 | B9: Rivals | C9: Mariona | D9: RZM | E9: 8 | F9: 1 | G9: 0
A10: RIV001 | B10: Rivals | C10: M. Salah | D10: RM | E10: 6.1 | F10: 0 | G10: 0
A11: RIV001 | B11: Rivals | C11: Jairzinho | D11: RM | E11: 8.9 | F11: 3 | G11: 0
A12: RIV001 | B12: Rivals | C12: S. Bacha | D12: LV | E12: 6.6 | F12: 0 | G12: 0
A13: RIV001 | B13: Rivals | C13: M. Bright | D13: LIV | E13: 7.5 | F13: 0 | G13: 0
A14: RIV001 | B14: Rivals | C14: G. Chiellini | D14: RIV | E14: 7.3 | F14: 0 | G14: 0
... A16: RIV001 | B16: Rivals | C16: T. Courtois | D16: TW | E16: 4 | F16: 0 | G16: 0
A17: RIV001 | B17: Rivals | C17: Marquinhos | D17: AW | F17: 0 | G17: 0
A18: RIV001 | B18: Rivals | C18: T. Bischof | D18: AW | F18: 0 | G18: 0
A19: RIV001 | B19: Rivals | C19: J. Zanetti | D19: AW | F19: 0 | G19: 0
