Workbook

Sheet Dashboard
B2: Statistics
B3: Main Squad | D3: Games | E3: Goals | F3: Assists | G3: Contributions | H3: MOTM | I3: Avg. Rating
B4: C. Pina | D4: =COUNTIFS( DataSpieler!C:C, $B4, DataSpieler!E:E, ">0", DataSpieler!B:B, IF(LOWER($L$5)="alle", "*", $L$5) ) -> 0 | E4: =SUMIFS(DataSpieler!F:F, DataSpieler!C:C, B4, DataSpieler!B:B, IF(LOWER($L$5)="alle","*", $L$5)) -> 0 | F4: =SUMIFS(DataSpieler!G:G, DataSpieler!C:C, B4, DataSpieler!B:B, IF(LOWER($L$5)="alle","*", $L$5)) -> 0 | G4: =E4+F4 -> 0 | H4: =COUNTIFS(DataSpieler!C:C, B4, DataSpieler!H:H,"x", DataSpieler!B:B, IF(LOWER($L$5)="alle","*", $L$5)) -> 0 | I4: =IFERROR(AVERAGEIFS(DataSpieler!E:E, DataSpieler!C:C, B4, DataSpieler!B:B, IF(LOWER($L$5)="alle","*", $L$5)), "")
B5: J. Cruyff | D5: =COUNTIFS( DataSpieler!C:C, $B5, DataSpieler!E:E, ">0", DataSpieler!B:B, IF(LOWER($L$5)="alle", "*", $L$5) ) -> 0 | E5: =SUMIFS(DataSpieler!F:F, DataSpieler!C:C, B5, DataSpieler!B:B, IF(LOWER($L$5)="alle","*", $L$5)) -> 0 | F5: =SUMIFS(DataSpieler!G:G, DataSpieler!C:C, B5, DataSpieler!B:B, IF(LOWER($L$5)="alle","*", $L$5)) -> 0 | G5: =E5+F5 -> 0 | H5: =COUNTIFS(DataSpieler!C:C, B5, DataSpieler!H:H,"x", DataSpieler!B:B, IF(LOWER($L$5)="alle","*", $L$5)) -> 0 | I5: =IFERROR(AVERAGEIFS(DataSpieler!E:E, DataSpieler!C:C, B5, DataSpieler!B:B, IF(LOWER($L$5)="alle","*", $L$5)), "") | K5: Spieltyp | L5: Alle
B6: R. Costa | D6: =COUNTIFS( DataSpieler!C:C, $B6, DataSpieler!E:E, ">0", DataSpieler!B:B, IF(LOWER($L$5)="alle", "*", $L$5) ) -> 0 | E6: =SUMIFS(DataSpieler!F:F, DataSpieler!C:C, B6, DataSpieler!B:B, IF(LOWER($L$5)="alle","*", $L$5)) -> 0 | F6: =SUMIFS(DataSpieler!G:G, DataSpieler!C:C, B6, DataSpieler!B:B, IF(LOWER($L$5)="alle","*", $L$5)) -> 0 | G6: =E6+F6 -> 0 | H6: =COUNTIFS(DataSpieler!C:C, B6, DataSpieler!H:H,"x", DataSpieler!B:B, IF(LOWER($L$5)="alle","*", $L$5)) -> 0 | I6: =IFERROR(AVERAGEIFS(DataSpieler!E:E, DataSpieler!C:C, B6, DataSpieler!B:B, IF(LOWER($L$5)="alle","*", $L$5)), "")
B7: M. Salah | D7: =COUNTIFS( DataSpieler!C:C, $B7, DataSpieler!E:E, ">0", DataSpieler!B:B, IF(LOWER($L$5)="alle", "*", $L$5) ) -> 0 | E7: =SUMIFS(DataSpieler!F:F, DataSpieler!C:C, B7, DataSpieler!B:B, IF(LOWER($L$5)="alle","*", $L$5)) -> 0 | F7: =SUMIFS(DataSpieler!G:G, DataSpieler!C:C, B7, DataSpieler!B:B, IF(LOWER($L$5)="alle","*", $L$5)) -> 0 | G7: =E7+F7 -> 0 | H7: =COUNTIFS(DataSpieler!C:C, B7, DataSpieler!H:H,"x", DataSpieler!B:B, IF(LOWER($L$5)="alle","*", $L$5)) -> 0 | I7: =IFERROR(AVERAGEIFS(DataSpieler!E:E, DataSpieler!C:C, B7, DataSpieler!B:B, IF(LOWER($L$5)="alle","*", $L$5)), "")
B8: F. Valverde | D8: =COUNTIFS( DataSpieler!C:C, $B8, DataSpieler!E:E, ">0", DataSpieler!B:B, IF(LOWER($L$5)="alle", "*", $L$5) ) -> 0 | E8: =SUMIFS(DataSpieler!F:F, DataSpieler!C:C, B8, DataSpieler!B:B, IF(LOWER($L$5)="alle","*", $L$5)) -> 0 | F8: =SUMIFS(DataSpieler!G:G, DataSpieler!C:C, B8, DataSpieler!B:B, IF(LOWER($L$5)="alle","*", $L$5)) -> 0 | G8: =E8+F8 -> 0 | H8: =COUNTIFS(DataSpieler!C:C, B8, DataSpieler!H:H,"x", DataSpieler!B:B, IF(LOWER($L$5)="alle","*", $L$5)) -> 0 | I8: =IFERROR(AVERAGEIFS(DataSpieler!E:E, DataSpieler!C:C, B8, DataSpieler!B:B, IF(LOWER($L$5)="alle","*", $L$5)), "")
B9: M. Essien | D9: =COUNTIFS( DataSpieler!C:C, $B9, DataSpieler!E:E, ">0", DataSpieler!B:B, IF(LOWER($L$5)="alle", "*", $L$5) ) -> 0 | E9: =SUMIFS(DataSpieler!F:F, DataSpieler!C:C, B9, DataSpieler!B:B, IF(LOWER($L$5)="alle","*", $L$5)) -> 0 | F9: =SUMIFS(DataSpieler!G:G, DataSpieler!C:C, B9, DataSpieler!B:B, IF(LOWER($L$5)="alle","*", $L$5)) -> 0 | G9: =E9+F9 -> 0 | H9: =COUNTIFS(DataSpieler!C:C, B9, DataSpieler!H:H,"x", DataSpieler!B:B, IF(LOWER($L$5)="alle","*", $L$5)) -> 0 | I9: =IFERROR(AVERAGEIFS(DataSpieler!E:E, DataSpieler!C:C, B9, DataSpieler!B:B, IF(LOWER($L$5)="alle","*", $L$5)), "")
B10: J. Alba | D10: =COUNTIFS( DataSpieler!C:C, $B10, DataSpieler!E:E, ">0", DataSpieler!B:B, IF(LOWER($L$5)="alle", "*", $L$5) ) -> 0 | E10: =SUMIFS(DataSpieler!F:F, DataSpieler!C:C, B10, DataSpieler!B:B, IF(LOWER($L$5)="alle","*", $L$5)) -> 0 | F10: =SUMIFS(DataSpieler!G:G, DataSpieler!C:C, B10, DataSpieler!B:B, IF(LOWER($L$5)="alle","*", $L$5)) -> 0 | G10: =E10+F10 -> 0 | H10: =COUNTIFS(DataSpieler!C:C, B10, DataSpieler!H:H,"x", DataSpieler!B:B, IF(LOWER($L$5)="alle","*", $L$5)) -> 0 | I10: =IFERROR(AVERAGEIFS(DataSpieler!E:E, DataSpieler!C:C, B10, DataSpieler!B:B, IF(LOWER($L$5)="alle","*", $L$5)), "")
B11: M. Lacroix | D11: =COUNTIFS( DataSpieler!C:C, $B11, DataSpieler!E:E, ">0", DataSpieler!B:B, IF(LOWER($L$5)="alle", "*", $L$5) ) -> 0 | E11: =SUMIFS(DataSpieler!F:F, DataSpieler!C:C, B11, DataSpieler!B:B, IF(LOWER($L$5)="alle","*", $L$5)) -> 0 | F11: =SUMIFS(DataSpieler!G:G, DataSpieler!C:C, B11, DataSpieler!B:B, IF(LOWER($L$5)="alle","*", $L$5)) -> 0 | G11: =E11+F11 -> 0 | H11: =COUNTIFS(DataSpieler!C:C, B11, DataSpieler!H:H,"x", DataSpieler!B:B, IF(LOWER($L$5)="alle","*", $L$5)) -> 0 | I11: =IFERROR(AVERAGEIFS(DataSpieler!E:E, DataSpieler!C:C, B11, DataSpieler!B:B, IF(LOWER($L$5)="alle","*", $L$5)), "")
B12: G. Chiellini | D12: =COUNTIFS( DataSpieler!C:C, $B12, DataSpieler!E:E, ">0", DataSpieler!B:B, IF(LOWER($L$5)="alle", "*", $L$5) ) -> 0 | E12: =SUMIFS(DataSpieler!F:F, DataSpieler!C:C, B12, DataSpieler!B:B, IF(LOWER($L$5)="alle","*", $L$5)) -> 0 | F12: =SUMIFS(DataSpieler!G:G, DataSpieler!C:C, B12, DataSpieler!B:B, IF(LOWER($L$5)="alle","*", $L$5)) -> 0 | G12: =E12+F12 -> 0 | H12: =COUNTIFS(DataSpieler!C:C, B12, DataSpieler!H:H,"x", DataSpieler!B:B, IF(LOWER($L$5)="alle","*", $L$5)) -> 0 | I12: =IFERROR(AVERAGEIFS(DataSpieler!E:E, DataSpieler!C:C, B12, DataSpieler!B:B, IF(LOWER($L$5)="alle","*", $L$5)), "")
B13: G. Zambrotta | D13: =COUNTIFS( DataSpieler!C:C, $B13, DataSpieler!E:E, ">0", DataSpieler!B:B, IF(LOWER($L$5)="alle", "*", $L$5) ) -> 0 | E13: =SUMIFS(DataSpieler!F:F, DataSpieler!C:C, B13, DataSpieler!B:B, IF(LOWER($L$5)="alle","*", $L$5)) -> 0 | F13: =SUMIFS(DataSpieler!G:G, DataSpieler!C:C, B13, DataSpieler!B:B, IF(LOWER($L$5)="alle","*", $L$5)) -> 0 | G13: =E13+F13 -> 0 | H13: =COUNTIFS(DataSpieler!C:C, B13, DataSpieler!H:H,"x", DataSpieler!B:B, IF(LOWER($L$5)="alle","*", $L$5)) -> 0 | I13: =IFERROR(AVERAGEIFS(DataSpieler!E:E, DataSpieler!C:C, B13, DataSpieler!B:B, IF(LOWER($L$5)="alle","*", $L$5)), "")
B14: T. Courtois | D14: =COUNTIFS( DataSpieler!C:C, $B14, DataSpieler!E:E, ">0", DataSpieler!B:B, IF(LOWER($L$5)="alle", "*", $L$5) ) -> 0 | E14: =SUMIFS(DataSpieler!F:F, DataSpieler!C:C, B14, DataSpieler!B:B, IF(LOWER($L$5)="alle","*", $L$5)) -> 0 | F14: =SUMIFS(DataSpieler!G:G, DataSpieler!C:C, B14, DataSpieler!B:B, IF(LOWER($L$5)="alle","*", $L$5)) -> 0 | G14: =E14+F14 -> 0 | H14: =COUNTIFS(DataSpieler!C:C, B14, DataSpieler!H:H,"x", DataSpieler!B:B, IF(LOWER($L$5)="alle","*", $L$5)) -> 0 | I14: =IFERROR(AVERAGEIFS(DataSpieler!E:E, DataSpieler!C:C, B14, DataSpieler!B:B, IF(LOWER($L$5)="alle","*", $L$5)), "")
B15: Bench | D15: Games | E15: Goals | F15: Assists | G15: Contributions | H15: MOTM | I15: Avg. Rating
B16: P. Dybala | D16: =COUNTIFS( DataSpieler!C:C, $B16, DataSpieler!E:E, ">0", DataSpieler!B:B, IF(LOWER($L$5)="alle", "*", $L$5) ) -> 0 | E16: =SUMIFS(DataSpieler!F:F, DataSpieler!C:C, B16, DataSpieler!B:B, IF(LOWER($L$5)="alle","*", $L$5)) -> 0 | F16: =SUMIFS(DataSpieler!G:G, DataSpieler!C:C, B16, DataSpieler!B:B, IF(LOWER($L$5)="alle","*", $L$5)) -> 0 | G16: =E16+F16 -> 0 | H16: =COUNTIFS(DataSpieler!C:C, B16, DataSpieler!H:H,"x", DataSpieler!B:B, IF(LOWER($L$5)="alle","*", $L$5)) -> 0 | I16: =IFERROR(AVERAGEIFS(DataSpieler!E:E, DataSpieler!C:C, B16, DataSpieler!B:B, IF(LOWER($L$5)="alle","*", $L$5)), "")
B17: G. Reiten | D17: =COUNTIFS( DataSpieler!C:C, $B17, DataSpieler!E:E, ">0", DataSpieler!B:B, IF(LOWER($L$5)="alle", "*", $L$5) ) -> 0 | E17: =SUMIFS(DataSpieler!F:F, DataSpieler!C:C, B17, DataSpieler!B:B, IF(LOWER($L$5)="alle","*", $L$5)) -> 0 | F17: =SUMIFS(DataSpieler!G:G, DataSpieler!C:C, B17, DataSpieler!B:B, IF(LOWER($L$5)="alle","*", $L$5)) -> 0 | G17: =E17+F17 -> 0 | H17: =COUNTIFS(DataSpieler!C:C, B17, DataSpieler!H:H,"x", DataSpieler!B:B, IF(LOWER($L$5)="alle","*", $L$5)) -> 0 | I17: =IFERROR(AVERAGEIFS(DataSpieler!E:E, DataSpieler!C:C, B17, DataSpieler!B:B, IF(LOWER($L$5)="alle","*", $L$5)), "")
B18: S. Mané | D18: =COUNTIFS( DataSpieler!C:C, $B18, DataSpieler!E:E, ">0", DataSpieler!B:B, IF(LOWER($L$5)="alle", "*", $L$5) ) -> 0 | E18: =SUMIFS(DataSpieler!F:F, DataSpieler!C:C, B18, DataSpieler!B:B, IF(LOWER($L$5)="alle","*", $L$5)) -> 0 | F18: =SUMIFS(DataSpieler!G:G, DataSpieler!C:C, B18, DataSpieler!B:B, IF(LOWER($L$5)="alle","*", $L$5)) -> 0 | G18: =E18+F18 -> 0 | H18: =COUNTIFS(DataSpieler!C:C, B18, DataSpieler!H:H,"x", DataSpieler!B:B, IF(LOWER($L$5)="alle","*", $L$5)) -> 0 | I18: =IFERROR(AVERAGEIFS(DataSpieler!E:E, DataSpieler!C:C, B18, DataSpieler!B:B, IF(LOWER($L$5)="alle","*", $L$5)), "")
B19: D. Sinani | D19: =COUNTIFS( DataSpieler!C:C, $B19, DataSpieler!E:E, ">0", DataSpieler!B:B, IF(LOWER($L$5)="alle", "*", $L$5) ) -> 0 | E19: =SUMIFS(DataSpieler!F:F, DataSpieler!C:C, B19, DataSpieler!B:B, IF(LOWER($L$5)="alle","*", $L$5)) -> 0 | F19: =SUMIFS(DataSpieler!G:G, DataSpieler!C:C, B19, DataSpieler!B:B, IF(LOWER($L$5)="alle","*", $L$5)) -> 0 | G19: =E19+F19 -> 0 | H19: =COUNTIFS(DataSpieler!C:C, B19, DataSpieler!H:H,"x", DataSpieler!B:B, IF(LOWER($L$5)="alle","*", $L$5)) -> 0 | I19: =IFERROR(AVERAGEIFS(DataSpieler!E:E, DataSpieler!C:C, B19, DataSpieler!B:B, IF(LOWER($L$5)="alle","*", $L$5)), "")
B20: Y. Hasegawa | D20: =COUNTIFS( DataSpieler!C:C, $B20, DataSpieler!E:E, ">0", DataSpieler!B:B, IF(LOWER($L$5)="alle", "*", $L$5) ) -> 0 | E20: =SUMIFS(DataSpieler!F:F, DataSpieler!C:C, B20, DataSpieler!B:B, IF(LOWER($L$5)="alle","*", $L$5)) -> 0 | F20: =SUMIFS(DataSpieler!G:G, DataSpieler!C:C, B20, DataSpieler!B:B, IF(LOWER($L$5)="alle","*", $L$5)) -> 0 | G20: =E20+F20 -> 0 | H20: =COUNTIFS(DataSpieler!C:C, B20, DataSpieler!H:H,"x", DataSpieler!B:B, IF(LOWER($L$5)="alle","*", $L$5)) -> 0 | I20: =IFERROR(AVERAGEIFS(DataSpieler!E:E, DataSpieler!C:C, B20, DataSpieler!B:B, IF(LOWER($L$5)="alle","*", $L$5)), "")
B21: J. Tah | D21: =COUNTIFS( DataSpieler!C:C, $B21, DataSpieler!E:E, ">0", DataSpieler!B:B, IF(LOWER($L$5)="alle", "*", $L$5) ) -> 0 | E21: =SUMIFS(DataSpieler!F:F, DataSpieler!C:C, B21, DataSpieler!B:B, IF(LOWER($L$5)="alle","*", $L$5)) -> 0 | F21: =SUMIFS(DataSpieler!G:G, DataSpieler!C:C, B21, DataSpieler!B:B, IF(LOWER($L$5)="alle","*", $L$5)) -> 0 | G21: =E21+F21 -> 0 | H21: =COUNTIFS(DataSpieler!C:C, B21, DataSpieler!H:H,"x", DataSpieler!B:B, IF(LOWER($L$5)="alle","*", $L$5)) -> 0 | I21: =IFERROR(AVERAGEIFS(DataSpieler!E:E, DataSpieler!C:C, B21, DataSpieler!B:B, IF(LOWER($L$5)="alle","*", $L$5)), "")
B22: H. Sawa | D22: =COUNTIFS( DataSpieler!C:C, $B22, DataSpieler!E:E, ">0", DataSpieler!B:B, IF(LOWER($L$5)="alle", "*", $L$5) ) -> 0 | E22: =SUMIFS(DataSpieler!F:F, DataSpieler!C:C, B22, DataSpieler!B:B, IF(LOWER($L$5)="alle","*", $L$5)) -> 0 | F22: =SUMIFS(DataSpieler!G:G, DataSpieler!C:C, B22, DataSpieler!B:B, IF(LOWER($L$5)="alle","*", $L$5)) -> 0 | G22: =E22+F22 -> 0 | H22: =COUNTIFS(DataSpieler!C:C, B22, DataSpieler!H:H,"x", DataSpieler!B:B, IF(LOWER($L$5)="alle","*", $L$5)) -> 0 | I22: =IFERROR(AVERAGEIFS(DataSpieler!E:E, DataSpieler!C:C, B22, DataSpieler!B:B, IF(LOWER($L$5)="alle","*", $L$5)), "")
B23: Legacy | D23: Games | E23: Goals | F23: Assists | G23: Contributions | H23: MOTM | I23: Avg. Rating
B24: G. Zola | D24: =COUNTIFS( DataSpieler!C:C, $B24, DataSpieler!E:E, ">0", DataSpieler!B:B, IF(LOWER($L$5)="alle", "*", $L$5) ) -> 0 | E24: =SUMIFS(DataSpieler!F:F, DataSpieler!C:C, B24, DataSpieler!B:B, IF(LOWER($L$5)="alle","*", $L$5)) -> 0 | F24: =SUMIFS(DataSpieler!G:G, DataSpieler!C:C, B24, DataSpieler!B:B, IF(LOWER($L$5)="alle","*", $L$5)) -> 0 | G24: =E24+F24 -> 0 | H24: =COUNTIFS(DataSpieler!C:C, B24, DataSpieler!H:H,"x", DataSpieler!B:B, IF(LOWER($L$5)="alle","*", $L$5)) -> 0 | I24: =IFERROR(AVERAGEIFS(DataSpieler!E:E, DataSpieler!C:C, B24, DataSpieler!B:B, IF(LOWER($L$5)="alle","*", $L$5)), "")
B25: W. Pacho | D25: =COUNTIFS( DataSpieler!C:C, $B25, DataSpieler!E:E, ">0", DataSpieler!B:B, IF(LOWER($L$5)="alle", "*", $L$5) ) -> 0 | E25: =SUMIFS(DataSpieler!F:F, DataSpieler!C:C, B25, DataSpieler!B:B, IF(LOWER($L$5)="alle","*", $L$5)) -> 0 | F25: =SUMIFS(DataSpieler!G:G, DataSpieler!C:C, B25, DataSpieler!B:B, IF(LOWER($L$5)="alle","*", $L$5)) -> 0 | G25: =E25+F25 -> 0 | H25: =COUNTIFS(DataSpieler!C:C, B25, DataSpieler!H:H,"x", DataSpieler!B:B, IF(LOWER($L$5)="alle","*", $L$5)) -> 0 | I25: =IFERROR(AVERAGEIFS(DataSpieler!E:E, DataSpieler!C:C, B25, DataSpieler!B:B, IF(LOWER($L$5)="alle","*", $L$5)), "")
B26: J. Scott | D26: =COUNTIFS( DataSpieler!C:C, $B26, DataSpieler!E:E, ">0", DataSpieler!B:B, IF(LOWER($L$5)="alle", "*", $L$5) ) -> 0 | E26: =SUMIFS(DataSpieler!F:F, DataSpieler!C:C, B26, DataSpieler!B:B, IF(LOWER($L$5)="alle","*", $L$5)) -> 0 | F26: =SUMIFS(DataSpieler!G:G, DataSpieler!C:C, B26, DataSpieler!B:B, IF(LOWER($L$5)="alle","*", $L$5)) -> 0 | G26: =E26+F26 -> 0 | H26: =COUNTIFS(DataSpieler!C:C, B26, DataSpieler!H:H,"x", DataSpieler!B:B, IF(LOWER($L$5)="alle","*", $L$5)) -> 0 | I26: =IFERROR(AVERAGEIFS(DataSpieler!E:E, DataSpieler!C:C, B26, DataSpieler!B:B, IF(LOWER($L$5)="alle","*", $L$5)), "")
B28: Current Record | F28: Goals Difference | I28: Clean Sheets
B29: Won | C29: Lost | D29: Draw | F29: Scored | G29: Conceded
B30: =COUNTIFS(DataSpiele!H:H, "Sieg", DataSpiele!B:B, IF(LOWER($L$5)="alle","*", $L$5)) -> 0 | C30: =COUNTIFS(DataSpiele!H:H, "Niederlage", DataSpiele!B:B, IF(LOWER($L$5)="alle","*", $L$5)) -> 0 | D30: =COUNTIFS(DataSpiele!H:H, "Unentschieden", DataSpiele!B:B, IF(LOWER($L$5)="alle","*", $L$5)) -> 0 | F30: =SUMIFS(DataSpiele!D:D,DataSpiele!I:I,"Heim",DataSpiele!B:B,IF(LOWER($L$5)="alle","*", $L$5))+SUMIFS(DataSpiele!E:E,DataSpiele!I:I,"Gast",DataSpiele!B:B,IF(LOWER($L$5)="alle","*", $L$5)) -> 0 | G30: =SUMIFS(DataSpiele!D:D,DataSpiele!I:I,"Gast",DataSpiele!B:B,IF(LOWER($L$5)="alle","*", $L$5))+SUMIFS(DataSpiele!E:E,DataSpiele!I:I,"Heim",DataSpiele!B:B,IF(LOWER($L$5)="alle","*", $L$5)) -> 0 | I30: =COUNTIFS(DataSpiele!Z:Z, "ja", DataSpiele!B:B, IF(LOWER($L$5)="alle","*", $L$5)) -> 0
B32: Rage Quit | C32: ET | F32: Avg Goals | G32: Avg Goals
B33: =COUNTIFS(DataSpiele!X:X,"Gegner hat aufgegeben (Sieg)", DataSpiele!B:B, IF(LOWER($L$5)="alle","*", $L$5)) -> 0 | C33: =COUNTIF(L:M,"ET") -> 0 | F33: =F30/D4 -> #DIV/0! | G33: =G30/D4 -> #DIV/0! | I33: Avg. Posession
I35: =IFERROR(AVERAGEIFS(DataSpiele!J:J, DataSpiele!B:B, IF(LOWER($L$5)="alle","*", $L$5)), " ")
F36: Max Win Streak | G36: =_xlfn.MAXIFS(D57:D71,C57:C71,"Sieg") -> 0
B39: Top Goals | C39: =INDEX(B4:B22,MATCH(C41,E4:E22,0)) -> C. Pina | D39: =INDEX(B4:B22,MATCH(D41,E4:E22,0)) -> C. Pina | E39: =INDEX(B4:B22,MATCH(E41,E4:E22,0)) -> C. Pina | G39: xG | H39: For | I39: Against
C41: =LARGE(E1:E21, 1) -> 0 | D41: =LARGE(E1:E21, 2) -> 0 | E41: =LARGE(E1:E21, 3) -> 0 | G41: Total | H41: =IFERROR(SUMIFS(DataSpiele!O:O, DataSpiele!B:B, IF(LOWER($L$5)="alle","*", $L$5)), " ") -> 0 | I41: =IFERROR(SUMIFS(DataSpiele!P:P, DataSpiele!B:B, IF(LOWER($L$5)="alle","*", $L$5)), " ") -> 0
G42: Average | H42: =IFERROR(AVERAGEIFS(DataSpiele!O:O, DataSpiele!B:B, IF(LOWER($L$5)="alle","*", $L$5)), " ") | I42: =IFERROR(AVERAGEIFS(DataSpiele!P:P, DataSpiele!B:B, IF(LOWER($L$5)="alle","*", $L$5)), " ")
B44: Top Assist | C44: =INDEX(B4:B22,MATCH(C46,F4:F22,0)) -> C. Pina | D44: =INDEX(B4:B22,MATCH(D46,F4:F22,0)) -> C. Pina | E44: =INDEX(B4:B22,MATCH(E46,F4:F22,0)) -> C. Pina | G44: Passing | H44: For | I44: Against
C46: =LARGE($F$3:$F$22, 1) -> 0 | D46: =LARGE($F$3:$F$22, 2) -> 0 | E46: =LARGE($F$3:$F$22, 3) -> 0 | G46: Total per Game | H46: =IFERROR(AVERAGEIFS(DataSpiele!Q:Q, DataSpiele!B:B, IF(LOWER($L$5)="alle","*", $L$5)), " ") | I46: =IFERROR(AVERAGEIFS(DataSpiele!R:R, DataSpiele!B:B, IF(LOWER($L$5)="alle","*", $L$5)), " ")
G47: Pass % | H47: =IFERROR(AVERAGEIFS(DataSpiele!S:S, DataSpiele!B:B, IF(LOWER($L$5)="alle","*", $L$5)), " ") | I47: =IFERROR(AVERAGEIFS(DataSpiele!T:T, DataSpiele!B:B, IF(LOWER($L$5)="alle","*", $L$5)), " ")
B49: Best Avg. Rating | C49: =INDEX(B4:B22,MATCH(C51,I4:I22,0)) -> #NUM! | D49: =INDEX(B4:B22,MATCH(D51,I4:I22,0)) -> #NUM! | E49: =INDEX(B4:B22,MATCH(E51,I4:I22,0)) -> #NUM! | G49: Shooting | H49: For | I49: Against
C51: =LARGE(I4:I22,1) -> #NUM! | D51: =LARGE(I4:I22,2) -> #NUM! | E51: =LARGE(I4:I22,3) -> #NUM! | G51: Total per Game | H51: =IFERROR(AVERAGEIFS(DataSpiele!K:K, DataSpiele!B:B, IF(LOWER($L$5)="alle","*", $L$5)), " ") | I51: =IFERROR(AVERAGEIFS(DataSpiele!L:L, DataSpiele!B:B, IF(LOWER($L$5)="alle","*", $L$5)), " ")
...

Sheet DataSpiele
A1: SpielID | B1: Spielkategorie | C1: Datum | D1: HeimT | E1: AuswärtsT | F1: Heim | G1: Auswärts | H1: Ergebnis | I1: Wo | J1: Ballbesitiz | K1: Schüsse | L1: SchüsseOpp | M1: Schusspräzision | N1: SchusspräzisionOpp | O1: xGoals | P1: xGoalsOpp | Q1: Pässe | R1: PässeOpp | S1: Erfolgreiche Pässe | T1: Erfolgreiche Pässe Opp | U1: Erfolgreiche Dribblings | V1: Gelbe Karten | W1: Rote Karten | X1: Abbruchgrund | Y1: Spieldauer | Z1: CleanSheet | AA1: Verlängerung

Sheet DataSpieler
A1: SpielID | B1: Spielkategorie | C1: Name | D1: Position | E1: Bewertung | F1: Tore | G1: Vorlagen | H1: MOTM | I1: Kommentar KI
