Workbook

Sheet Dashboard
A1: SpieleIDs
A2: {=_xlfn.LET( _xlpm.Kat,Dashboard!$M$5, _xlpm.Xraw,Dashboard!$M$6, _xlpm.IstallKat,AND(ISTEXT(_xlpm.Kat),LOWER(_xlpm.Kat)="all"), _xlpm.IstallX,AND(ISTEXT(_xlpm.Xraw),LOWER(_xlpm.Xraw)="all"), _xlpm.IDs0,DataGames!$A$2:$A$99987, _xlpm.Kats0,DataGames!$B$2:$B$99987, _xlpm.IDs,_xlfn._xlws.FILTER(_xlpm.IDs0,_xlpm.IDs0<>""), _xlpm.Kats,_xlfn._xlws.FILTER(_xlpm.Kats0,_xlpm.IDs0<>""), _xlpm.IDsGef,_xlfn._xlws.FILTER(_xlpm.IDs,IF(_xlpm.IstallKat,TRUE,_xlpm.Kats=_xlpm.Kat)), _xlpm.n,ROWS(_xlpm.IDsGef), _xlpm.X,IF(_xlpm.IstallX,_xlpm.n,IFERROR(--_xlpm.Xraw,VALUE(_xlpm.Xraw))), _xlpm.k,MIN(_xlpm.X,_xlpm.n), INDEX(_xlpm.IDsGef,_xlfn.SEQUENCE(_xlpm.k,1,_xlpm.n-_xlpm.k+1,1)) )} -> RIV1 | C2: Statistics
C3: Main Squad | E3: Games | F3: Goals | G3: Assists | H3: Contributions | I3: MOTM | J3: Avg. Rating
C4: J. Cruyff | E4: {=SUMPRODUCT( --(DataPlayer!$C$2:$C$99941=$C4), --(DataPlayer!$E$2:$E$99941>0), --ISNUMBER(MATCH(DataPlayer!$A$2:$A$99941,_xlfn.ANCHORARRAY($A$2),0)) )} -> 1 | F4: {=SUMPRODUCT( DataPlayer!$F$2:$F$99941, --(DataPlayer!$C$2:$C$99941=C4), --ISNUMBER(MATCH(DataPlayer!$A$2:$A$99941,_xlfn.ANCHORARRAY($A$2),0)) )} -> 2 | G4: {=SUMPRODUCT( DataPlayer!$G$2:$G$99941, --(DataPlayer!$C$2:$C$99941=C4), --ISNUMBER(MATCH(DataPlayer!$A$2:$A$99941,_xlfn.ANCHORARRAY($A$2),0)) )} -> 0 | H4: =F4+G4 -> 2 | I4: {=SUMPRODUCT( --(DataPlayer!$C$2:$C$99941=C4), --(DataPlayer!$H$2:$H$99941="x"), --ISNUMBER(MATCH(DataPlayer!$A$2:$A$99941,_xlfn.ANCHORARRAY($A$2),0)) )} -> 0 | J4: {=IFERROR( AVERAGE( _xlfn._xlws.FILTER( DataPlayer!$E$2:$E$99941, (DataPlayer!$C$2:$C$99941=C4) * ISNUMBER(MATCH(DataPlayer!$A$2:$A$99941,_xlfn.ANCHORARRAY($A$2),0)) ) ), "" )} -> 8.5
C5: S. Mané | E5: {=SUMPRODUCT( --(DataPlayer!$C$2:$C$99941=$C5), --(DataPlayer!$E$2:$E$99941>0), --ISNUMBER(MATCH(DataPlayer!$A$2:$A$99941,_xlfn.ANCHORARRAY($A$2),0)) )} -> 1 | F5: {=SUMPRODUCT( DataPlayer!$F$2:$F$99941, --(DataPlayer!$C$2:$C$99941=C5), --ISNUMBER(MATCH(DataPlayer!$A$2:$A$99941,_xlfn.ANCHORARRAY($A$2),0)) )} -> 0 | G5: {=SUMPRODUCT( DataPlayer!$G$2:$G$99941, --(DataPlayer!$C$2:$C$99941=C5), --ISNUMBER(MATCH(DataPlayer!$A$2:$A$99941,_xlfn.ANCHORARRAY($A$2),0)) )} -> 0 | H5: =F5+G5 -> 0 | I5: {=SUMPRODUCT( --(DataPlayer!$C$2:$C$99941=C5), --(DataPlayer!$H$2:$H$99941="x"), --ISNUMBER(MATCH(DataPlayer!$A$2:$A$99941,_xlfn.ANCHORARRAY($A$2),0)) )} -> 0 | J5: {=IFERROR( AVERAGE( _xlfn._xlws.FILTER( DataPlayer!$E$2:$E$99941, (DataPlayer!$C$2:$C$99941=C5) * ISNUMBER(MATCH(DataPlayer!$A$2:$A$99941,_xlfn.ANCHORARRAY($A$2),0)) ) ), "" )} -> 6.2 | L5: Gametype | M5: all
C6: P. Dybala | E6: {=SUMPRODUCT( --(DataPlayer!$C$2:$C$99941=$C6), --(DataPlayer!$E$2:$E$99941>0), --ISNUMBER(MATCH(DataPlayer!$A$2:$A$99941,_xlfn.ANCHORARRAY($A$2),0)) )} -> 1 | F6: {=SUMPRODUCT( DataPlayer!$F$2:$F$99941, --(DataPlayer!$C$2:$C$99941=C6), --ISNUMBER(MATCH(DataPlayer!$A$2:$A$99941,_xlfn.ANCHORARRAY($A$2),0)) )} -> 0 | G6: {=SUMPRODUCT( DataPlayer!$G$2:$G$99941, --(DataPlayer!$C$2:$C$99941=C6), --ISNUMBER(MATCH(DataPlayer!$A$2:$A$99941,_xlfn.ANCHORARRAY($A$2),0)) )} -> 0 | H6: =F6+G6 -> 0 | I6: {=SUMPRODUCT( --(DataPlayer!$C$2:$C$99941=C6), --(DataPlayer!$H$2:$H$99941="x"), --ISNUMBER(MATCH(DataPlayer!$A$2:$A$99941,_xlfn.ANCHORARRAY($A$2),0)) )} -> 0 | J6: {=IFERROR( AVERAGE( _xlfn._xlws.FILTER( DataPlayer!$E$2:$E$99941, (DataPlayer!$C$2:$C$99941=C6) * ISNUMBER(MATCH(DataPlayer!$A$2:$A$99941,_xlfn.ANCHORARRAY($A$2),0)) ) ), "" )} -> 6.5 | L6: Number of Games | M6: all
C7: M. Salah | E7: {=SUMPRODUCT( --(DataPlayer!$C$2:$C$99941=$C7), --(DataPlayer!$E$2:$E$99941>0), --ISNUMBER(MATCH(DataPlayer!$A$2:$A$99941,_xlfn.ANCHORARRAY($A$2),0)) )} -> 1 | F7: {=SUMPRODUCT( DataPlayer!$F$2:$F$99941, --(DataPlayer!$C$2:$C$99941=C7), --ISNUMBER(MATCH(DataPlayer!$A$2:$A$99941,_xlfn.ANCHORARRAY($A$2),0)) )} -> 2 | G7: {=SUMPRODUCT( DataPlayer!$G$2:$G$99941, --(DataPlayer!$C$2:$C$99941=C7), --ISNUMBER(MATCH(DataPlayer!$A$2:$A$99941,_xlfn.ANCHORARRAY($A$2),0)) )} -> 1 | H7: =F7+G7 -> 3 | I7: {=SUMPRODUCT( --(DataPlayer!$C$2:$C$99941=C7), --(DataPlayer!$H$2:$H$99941="x"), --ISNUMBER(MATCH(DataPlayer!$A$2:$A$99941,_xlfn.ANCHORARRAY($A$2),0)) )} -> 0 | J7: {=IFERROR( AVERAGE( _xlfn._xlws.FILTER( DataPlayer!$E$2:$E$99941, (DataPlayer!$C$2:$C$99941=C7) * ISNUMBER(MATCH(DataPlayer!$A$2:$A$99941,_xlfn.ANCHORARRAY($A$2),0)) ) ), "" )} -> 8.3
C8: D. Sinani | E8: {=SUMPRODUCT( --(DataPlayer!$C$2:$C$99941=$C8), --(DataPlayer!$E$2:$E$99941>0), --ISNUMBER(MATCH(DataPlayer!$A$2:$A$99941,_xlfn.ANCHORARRAY($A$2),0)) )} -> 1 | F8: {=SUMPRODUCT( DataPlayer!$F$2:$F$99941, --(DataPlayer!$C$2:$C$99941=C8), --ISNUMBER(MATCH(DataPlayer!$A$2:$A$99941,_xlfn.ANCHORARRAY($A$2),0)) )} -> 0 | G8: {=SUMPRODUCT( DataPlayer!$G$2:$G$99941, --(DataPlayer!$C$2:$C$99941=C8), --ISNUMBER(MATCH(DataPlayer!$A$2:$A$99941,_xlfn.ANCHORARRAY($A$2),0)) )} -> 0 | H8: =F8+G8 -> 0 | I8: {=SUMPRODUCT( --(DataPlayer!$C$2:$C$99941=C8), --(DataPlayer!$H$2:$H$99941="x"), --ISNUMBER(MATCH(DataPlayer!$A$2:$A$99941,_xlfn.ANCHORARRAY($A$2),0)) )} -> 0 | J8: {=IFERROR( AVERAGE( _xlfn._xlws.FILTER( DataPlayer!$E$2:$E$99941, (DataPlayer!$C$2:$C$99941=C8) * ISNUMBER(MATCH(DataPlayer!$A$2:$A$99941,_xlfn.ANCHORARRAY($A$2),0)) ) ), "" )} -> 6.8
C9: F. Valverde | E9: {=SUMPRODUCT( --(DataPlayer!$C$2:$C$99941=$C9), --(DataPlayer!$E$2:$E$99941>0), --ISNUMBER(MATCH(DataPlayer!$A$2:$A$99941,_xlfn.ANCHORARRAY($A$2),0)) )} -> 1 | F9: {=SUMPRODUCT( DataPlayer!$F$2:$F$99941, --(DataPlayer!$C$2:$C$99941=C9), --ISNUMBER(MATCH(DataPlayer!$A$2:$A$99941,_xlfn.ANCHORARRAY($A$2),0)) )} -> 0 | G9: {=SUMPRODUCT( DataPlayer!$G$2:$G$99941, --(DataPlayer!$C$2:$C$99941=C9), --ISNUMBER(MATCH(DataPlayer!$A$2:$A$99941,_xlfn.ANCHORARRAY($A$2),0)) )} -> 0 | H9: =F9+G9 -> 0 | I9: {=SUMPRODUCT( --(DataPlayer!$C$2:$C$99941=C9), --(DataPlayer!$H$2:$H$99941="x"), --ISNUMBER(MATCH(DataPlayer!$A$2:$A$99941,_xlfn.ANCHORARRAY($A$2),0)) )} -> 0 | J9: {=IFERROR( AVERAGE( _xlfn._xlws.FILTER( DataPlayer!$E$2:$E$99941, (DataPlayer!$C$2:$C$99941=C9) * ISNUMBER(MATCH(DataPlayer!$A$2:$A$99941,_xlfn.ANCHORARRAY($A$2),0)) ) ), "" )} -> 6.7
C10: J. Alba | E10: {=SUMPRODUCT( --(DataPlayer!$C$2:$C$99941=$C10), --(DataPlayer!$E$2:$E$99941>0), --ISNUMBER(MATCH(DataPlayer!$A$2:$A$99941,_xlfn.ANCHORARRAY($A$2),0)) )} -> 1 | F10: {=SUMPRODUCT( DataPlayer!$F$2:$F$99941, --(DataPlayer!$C$2:$C$99941=C10), --ISNUMBER(MATCH(DataPlayer!$A$2:$A$99941,_xlfn.ANCHORARRAY($A$2),0)) )} -> 0 | G10: {=SUMPRODUCT( DataPlayer!$G$2:$G$99941, --(DataPlayer!$C$2:$C$99941=C10), --ISNUMBER(MATCH(DataPlayer!$A$2:$A$99941,_xlfn.ANCHORARRAY($A$2),0)) )} -> 0 | H10: =F10+G10 -> 0 | I10: {=SUMPRODUCT( --(DataPlayer!$C$2:$C$99941=C10), --(DataPlayer!$H$2:$H$99941="x"), --ISNUMBER(MATCH(DataPlayer!$A$2:$A$99941,_xlfn.ANCHORARRAY($A$2),0)) )} -> 0 | J10: {=IFERROR( AVERAGE( _xlfn._xlws.FILTER( DataPlayer!$E$2:$E$99941, (DataPlayer!$C$2:$C$99941=C10) * ISNUMBER(MATCH(DataPlayer!$A$2:$A$99941,_xlfn.ANCHORARRAY($A$2),0)) ) ), "" )} -> 6.8
C11: W. Pacho | E11: {=SUMPRODUCT( --(DataPlayer!$C$2:$C$99941=$C11), --(DataPlayer!$E$2:$E$99941>0), --ISNUMBER(MATCH(DataPlayer!$A$2:$A$99941,_xlfn.ANCHORARRAY($A$2),0)) )} -> 1 | F11: {=SUMPRODUCT( DataPlayer!$F$2:$F$99941, --(DataPlayer!$C$2:$C$99941=C11), --ISNUMBER(MATCH(DataPlayer!$A$2:$A$99941,_xlfn.ANCHORARRAY($A$2),0)) )} -> 0 | G11: {=SUMPRODUCT( DataPlayer!$G$2:$G$99941, --(DataPlayer!$C$2:$C$99941=C11), --ISNUMBER(MATCH(DataPlayer!$A$2:$A$99941,_xlfn.ANCHORARRAY($A$2),0)) )} -> 0 | H11: =F11+G11 -> 0 | I11: {=SUMPRODUCT( --(DataPlayer!$C$2:$C$99941=C11), --(DataPlayer!$H$2:$H$99941="x"), --ISNUMBER(MATCH(DataPlayer!$A$2:$A$99941,_xlfn.ANCHORARRAY($A$2),0)) )} -> 0 | J11: {=IFERROR( AVERAGE( _xlfn._xlws.FILTER( DataPlayer!$E$2:$E$99941, (DataPlayer!$C$2:$C$99941=C11) * ISNUMBER(MATCH(DataPlayer!$A$2:$A$99941,_xlfn.ANCHORARRAY($A$2),0)) ) ), "" )} -> 6.8
C12: G. Chiellini | E12: {=SUMPRODUCT( --(DataPlayer!$C$2:$C$99941=$C12), --(DataPlayer!$E$2:$E$99941>0), --ISNUMBER(MATCH(DataPlayer!$A$2:$A$99941,_xlfn.ANCHORARRAY($A$2),0)) )} -> 1 | F12: {=SUMPRODUCT( DataPlayer!$F$2:$F$99941, --(DataPlayer!$C$2:$C$99941=C12), --ISNUMBER(MATCH(DataPlayer!$A$2:$A$99941,_xlfn.ANCHORARRAY($A$2),0)) )} -> 0 | G12: {=SUMPRODUCT( DataPlayer!$G$2:$G$99941, --(DataPlayer!$C$2:$C$99941=C12), --ISNUMBER(MATCH(DataPlayer!$A$2:$A$99941,_xlfn.ANCHORARRAY($A$2),0)) )} -> 0 | H12: =F12+G12 -> 0 | I12: {=SUMPRODUCT( --(DataPlayer!$C$2:$C$99941=C12), --(DataPlayer!$H$2:$H$99941="x"), --ISNUMBER(MATCH(DataPlayer!$A$2:$A$99941,_xlfn.ANCHORARRAY($A$2),0)) )} -> 0 | J12: {=IFERROR( AVERAGE( _xlfn._xlws.FILTER( DataPlayer!$E$2:$E$99941, (DataPlayer!$C$2:$C$99941=C12) * ISNUMBER(MATCH(DataPlayer!$A$2:$A$99941,_xlfn.ANCHORARRAY($A$2),0)) ) ), "" )} -> 7.7
C13: G. Zambrotta | E13: {=SUMPRODUCT( --(DataPlayer!$C$2:$C$99941=$C13), --(DataPlayer!$E$2:$E$99941>0), --ISNUMBER(MATCH(DataPlayer!$A$2:$A$99941,_xlfn.ANCHORARRAY($A$2),0)) )} -> 1 | F13: {=SUMPRODUCT( DataPlayer!$F$2:$F$99941, --(DataPlayer!$C$2:$C$99941=C13), --ISNUMBER(MATCH(DataPlayer!$A$2:$A$99941,_xlfn.ANCHORARRAY($A$2),0)) )} -> 0 | G13: {=SUMPRODUCT( DataPlayer!$G$2:$G$99941, --(DataPlayer!$C$2:$C$99941=C13), --ISNUMBER(MATCH(DataPlayer!$A$2:$A$99941,_xlfn.ANCHORARRAY($A$2),0)) )} -> 0 | H13: =F13+G13 -> 0 | I13: {=SUMPRODUCT( --(DataPlayer!$C$2:$C$99941=C13), --(DataPlayer!$H$2:$H$99941="x"), --ISNUMBER(MATCH(DataPlayer!$A$2:$A$99941,_xlfn.ANCHORARRAY($A$2),0)) )} -> 0 | J13: {=IFERROR( AVERAGE( _xlfn._xlws.FILTER( DataPlayer!$E$2:$E$99941, (DataPlayer!$C$2:$C$99941=C13) * ISNUMBER(MATCH(DataPlayer!$A$2:$A$99941,_xlfn.ANCHORARRAY($A$2),0)) ) ), "" )} -> 6.5 | M13: test
C14: T. Courtois | E14: {=SUMPRODUCT( --(DataPlayer!$C$2:$C$99941=$C14), --(DataPlayer!$E$2:$E$99941>0), --ISNUMBER(MATCH(DataPlayer!$A$2:$A$99941,_xlfn.ANCHORARRAY($A$2),0)) )} -> 1 | F14: {=SUMPRODUCT( DataPlayer!$F$2:$F$99941, --(DataPlayer!$C$2:$C$99941=C14), --ISNUMBER(MATCH(DataPlayer!$A$2:$A$99941,_xlfn.ANCHORARRAY($A$2),0)) )} -> 0 | G14: {=SUMPRODUCT( DataPlayer!$G$2:$G$99941, --(DataPlayer!$C$2:$C$99941=C14), --ISNUMBER(MATCH(DataPlayer!$A$2:$A$99941,_xlfn.ANCHORARRAY($A$2),0)) )} -> 0 | H14: =F14+G14 -> 0 | I14: {=SUMPRODUCT( --(DataPlayer!$C$2:$C$99941=C14), --(DataPlayer!$H$2:$H$99941="x"), --ISNUMBER(MATCH(DataPlayer!$A$2:$A$99941,_xlfn.ANCHORARRAY($A$2),0)) )} -> 0 | J14: {=IFERROR( AVERAGE( _xlfn._xlws.FILTER( DataPlayer!$E$2:$E$99941, (DataPlayer!$C$2:$C$99941=C14) * ISNUMBER(MATCH(DataPlayer!$A$2:$A$99941,_xlfn.ANCHORARRAY($A$2),0)) ) ), "" )} -> 4
C15: Bench | E15: Games | F15: Goals | G15: Assists | H15: Contributions | I15: MOTM | J15: Avg. Rating
C16: C. Pina | E16: {=SUMPRODUCT( --(DataPlayer!$C$2:$C$99941=$C16), --(DataPlayer!$E$2:$E$99941>0), --ISNUMBER(MATCH(DataPlayer!$A$2:$A$99941,_xlfn.ANCHORARRAY($A$2),0)) )} -> 1 | F16: {=SUMPRODUCT( DataPlayer!$F$2:$F$99941, --(DataPlayer!$C$2:$C$99941=C16), --ISNUMBER(MATCH(DataPlayer!$A$2:$A$99941,_xlfn.ANCHORARRAY($A$2),0)) )} -> 1 | G16: {=SUMPRODUCT( DataPlayer!$G$2:$G$99941, --(DataPlayer!$C$2:$C$99941=C16), --ISNUMBER(MATCH(DataPlayer!$A$2:$A$99941,_xlfn.ANCHORARRAY($A$2),0)) )} -> 3 | H16: =F16+G16 -> 4 | I16: {=SUMPRODUCT( --(DataPlayer!$C$2:$C$99941=C16), --(DataPlayer!$H$2:$H$99941="x"), --ISNUMBER(MATCH(DataPlayer!$A$2:$A$99941,_xlfn.ANCHORARRAY($A$2),0)) )} -> 0 | J16: {=IFERROR( AVERAGE( _xlfn._xlws.FILTER( DataPlayer!$E$2:$E$99941, (DataPlayer!$C$2:$C$99941=C16) * ISNUMBER(MATCH(DataPlayer!$A$2:$A$99941,_xlfn.ANCHORARRAY($A$2),0)) ) ), "" )} -> 9.4
C17: P. Dybala | E17: {=SUMPRODUCT( --(DataPlayer!$C$2:$C$99941=$C17), --(DataPlayer!$E$2:$E$99941>0), --ISNUMBER(MATCH(DataPlayer!$A$2:$A$99941,_xlfn.ANCHORARRAY($A$2),0)) )} -> 1 | F17: {=SUMPRODUCT( DataPlayer!$F$2:$F$99941, --(DataPlayer!$C$2:$C$99941=C17), --ISNUMBER(MATCH(DataPlayer!$A$2:$A$99941,_xlfn.ANCHORARRAY($A$2),0)) )} -> 0 | G17: {=SUMPRODUCT( DataPlayer!$G$2:$G$99941, --(DataPlayer!$C$2:$C$99941=C17), --ISNUMBER(MATCH(DataPlayer!$A$2:$A$99941,_xlfn.ANCHORARRAY($A$2),0)) )} -> 0 | H17: =F17+G17 -> 0 | I17: {=SUMPRODUCT( --(DataPlayer!$C$2:$C$99941=C17), --(DataPlayer!$H$2:$H$99941="x"), --ISNUMBER(MATCH(DataPlayer!$A$2:$A$99941,_xlfn.ANCHORARRAY($A$2),0)) )} -> 0 | J17: {=IFERROR( AVERAGE( _xlfn._xlws.FILTER( DataPlayer!$E$2:$E$99941, (DataPlayer!$C$2:$C$99941=C17) * ISNUMBER(MATCH(DataPlayer!$A$2:$A$99941,_xlfn.ANCHORARRAY($A$2),0)) ) ), "" )} -> 6.5
C18: G. Reiten | E18: {=SUMPRODUCT( --(DataPlayer!$C$2:$C$99941=$C18), --(DataPlayer!$E$2:$E$99941>0), --ISNUMBER(MATCH(DataPlayer!$A$2:$A$99941,_xlfn.ANCHORARRAY($A$2),0)) )} -> 1 | F18: {=SUMPRODUCT( DataPlayer!$F$2:$F$99941, --(DataPlayer!$C$2:$C$99941=C18), --ISNUMBER(MATCH(DataPlayer!$A$2:$A$99941,_xlfn.ANCHORARRAY($A$2),0)) )} -> 0 | G18: {=SUMPRODUCT( DataPlayer!$G$2:$G$99941, --(DataPlayer!$C$2:$C$99941=C18), --ISNUMBER(MATCH(DataPlayer!$A$2:$A$99941,_xlfn.ANCHORARRAY($A$2),0)) )} -> 0 | H18: =F18+G18 -> 0 | I18: {=SUMPRODUCT( --(DataPlayer!$C$2:$C$99941=C18), --(DataPlayer!$H$2:$H$99941="x"), --ISNUMBER(MATCH(DataPlayer!$A$2:$A$99941,_xlfn.ANCHORARRAY($A$2),0)) )} -> 0 | J18: {=IFERROR( AVERAGE( _xlfn._xlws.FILTER( DataPlayer!$E$2:$E$99941, (DataPlayer!$C$2:$C$99941=C18) * ISNUMBER(MATCH(DataPlayer!$A$2:$A$99941,_xlfn.ANCHORARRAY($A$2),0)) ) ), "" )} -> 5.7
C19: P. Guijarro | E19: {=SUMPRODUCT( --(DataPlayer!$C$2:$C$99941=$C19), --(DataPlayer!$E$2:$E$99941>0), --ISNUMBER(MATCH(DataPlayer!$A$2:$A$99941,_xlfn.ANCHORARRAY($A$2),0)) )} -> 0 | F19: {=SUMPRODUCT( DataPlayer!$F$2:$F$99941, --(DataPlayer!$C$2:$C$99941=C19), --ISNUMBER(MATCH(DataPlayer!$A$2:$A$99941,_xlfn.ANCHORARRAY($A$2),0)) )} -> 0 | G19: {=SUMPRODUCT( DataPlayer!$G$2:$G$99941, --(DataPlayer!$C$2:$C$99941=C19), --ISNUMBER(MATCH(DataPlayer!$A$2:$A$99941,_xlfn.ANCHORARRAY($A$2),0)) )} -> 0 | H19: =F19+G19 -> 0 | I19: {=SUMPRODUCT( --(DataPlayer!$C$2:$C$99941=C19), --(DataPlayer!$H$2:$H$99941="x"), --ISNUMBER(MATCH(DataPlayer!$A$2:$A$99941,_xlfn.ANCHORARRAY($A$2),0)) )} -> 0 | J19: {=IFERROR( AVERAGE( _xlfn._xlws.FILTER( DataPlayer!$E$2:$E$99941, (DataPlayer!$C$2:$C$99941=C19) * ISNUMBER(MATCH(DataPlayer!$A$2:$A$99941,_xlfn.ANCHORARRAY($A$2),0)) ) ), "" )}
C20: M. Bombito | E20: {=SUMPRODUCT( --(DataPlayer!$C$2:$C$99941=$C20), --(DataPlayer!$E$2:$E$99941>0), --ISNUMBER(MATCH(DataPlayer!$A$2:$A$99941,_xlfn.ANCHORARRAY($A$2),0)) )} -> 0 | F20: {=SUMPRODUCT( DataPlayer!$F$2:$F$99941, --(DataPlayer!$C$2:$C$99941=C20), --ISNUMBER(MATCH(DataPlayer!$A$2:$A$99941,_xlfn.ANCHORARRAY($A$2),0)) )} -> 0 | G20: {=SUMPRODUCT( DataPlayer!$G$2:$G$99941, --(DataPlayer!$C$2:$C$99941=C20), --ISNUMBER(MATCH(DataPlayer!$A$2:$A$99941,_xlfn.ANCHORARRAY($A$2),0)) )} -> 0 | H20: =F20+G20 -> 0 | I20: {=SUMPRODUCT( --(DataPlayer!$C$2:$C$99941=C20), --(DataPlayer!$H$2:$H$99941="x"), --ISNUMBER(MATCH(DataPlayer!$A$2:$A$99941,_xlfn.ANCHORARRAY($A$2),0)) )} -> 0 | J20: {=IFERROR( AVERAGE( _xlfn._xlws.FILTER( DataPlayer!$E$2:$E$99941, (DataPlayer!$C$2:$C$99941=C20) * ISNUMBER(MATCH(DataPlayer!$A$2:$A$99941,_xlfn.ANCHORARRAY($A$2),0)) ) ), "" )}
C21: D. Sinani | E21: {=SUMPRODUCT( --(DataPlayer!$C$2:$C$99941=$C21), --(DataPlayer!$E$2:$E$99941>0), --ISNUMBER(MATCH(DataPlayer!$A$2:$A$99941,_xlfn.ANCHORARRAY($A$2),0)) )} -> 1 | F21: {=SUMPRODUCT( DataPlayer!$F$2:$F$99941, --(DataPlayer!$C$2:$C$99941=C21), --ISNUMBER(MATCH(DataPlayer!$A$2:$A$99941,_xlfn.ANCHORARRAY($A$2),0)) )} -> 0 | G21: {=SUMPRODUCT( DataPlayer!$G$2:$G$99941, --(DataPlayer!$C$2:$C$99941=C21), --ISNUMBER(MATCH(DataPlayer!$A$2:$A$99941,_xlfn.ANCHORARRAY($A$2),0)) )} -> 0 | H21: =F21+G21 -> 0 | I21: {=SUMPRODUCT( --(DataPlayer!$C$2:$C$99941=C21), --(DataPlayer!$H$2:$H$99941="x"), --ISNUMBER(MATCH(DataPlayer!$A$2:$A$99941,_xlfn.ANCHORARRAY($A$2),0)) )} -> 0 | J21: {=IFERROR( AVERAGE( _xlfn._xlws.FILTER( DataPlayer!$E$2:$E$99941, (DataPlayer!$C$2:$C$99941=C21) * ISNUMBER(MATCH(DataPlayer!$A$2:$A$99941,_xlfn.ANCHORARRAY($A$2),0)) ) ), "" )} -> 6.8
C22: A. Garnacho | E22: {=SUMPRODUCT( --(DataPlayer!$C$2:$C$99941=$C22), --(DataPlayer!$E$2:$E$99941>0), --ISNUMBER(MATCH(DataPlayer!$A$2:$A$99941,_xlfn.ANCHORARRAY($A$2),0)) )} -> 0 | F22: {=SUMPRODUCT( DataPlayer!$F$2:$F$99941, --(DataPlayer!$C$2:$C$99941=C22), --ISNUMBER(MATCH(DataPlayer!$A$2:$A$99941,_xlfn.ANCHORARRAY($A$2),0)) )} -> 0 | G22: {=SUMPRODUCT( DataPlayer!$G$2:$G$99941, --(DataPlayer!$C$2:$C$99941=C22), --ISNUMBER(MATCH(DataPlayer!$A$2:$A$99941,_xlfn.ANCHORARRAY($A$2),0)) )} -> 0 | H22: =F22+G22 -> 0 | I22: {=SUMPRODUCT( --(DataPlayer!$C$2:$C$99941=C22), --(DataPlayer!$H$2:$H$99941="x"), --ISNUMBER(MATCH(DataPlayer!$A$2:$A$99941,_xlfn.ANCHORARRAY($A$2),0)) )} -> 0 | J22: {=IFERROR( AVERAGE( _xlfn._xlws.FILTER( DataPlayer!$E$2:$E$99941, (DataPlayer!$C$2:$C$99941=C22) * ISNUMBER(MATCH(DataPlayer!$A$2:$A$99941,_xlfn.ANCHORARRAY($A$2),0)) ) ), "" )}
C23: Legacy | E23: Games | F23: Goals | G23: Assists | H23: Contributions | I23: MOTM | J23: Avg. Rating
E24: {=SUMPRODUCT( --(DataPlayer!$C$2:$C$99941=$C24), --(DataPlayer!$E$2:$E$99941>0), --ISNUMBER(MATCH(DataPlayer!$A$2:$A$99941,_xlfn.ANCHORARRAY($A$2),0)) )} -> 0 | F24: {=SUMPRODUCT( DataPlayer!$F$2:$F$99941, --(DataPlayer!$C$2:$C$99941=C24), --ISNUMBER(MATCH(DataPlayer!$A$2:$A$99941,_xlfn.ANCHORARRAY($A$2),0)) )} -> 0 | G24: {=SUMPRODUCT( DataPlayer!$G$2:$G$99941, --(DataPlayer!$C$2:$C$99941=C24), --ISNUMBER(MATCH(DataPlayer!$A$2:$A$99941,_xlfn.ANCHORARRAY($A$2),0)) )} -> 0 | H24: =F24+G24 -> 0 | I24: {=SUMPRODUCT( --(DataPlayer!$C$2:$C$99941=C24), --(DataPlayer!$H$2:$H$99941="x"), --ISNUMBER(MATCH(DataPlayer!$A$2:$A$99941,_xlfn.ANCHORARRAY($A$2),0)) )} -> 0 | J24: {=IFERROR( AVERAGE( _xlfn._xlws.FILTER( DataPlayer!$E$2:$E$99941, (DataPlayer!$C$2:$C$99941=C24) * ISNUMBER(MATCH(DataPlayer!$A$2:$A$99941,_xlfn.ANCHORARRAY($A$2),0)) ) ), "" )}
E25: {=SUMPRODUCT( --(DataPlayer!$C$2:$C$99941=$C25), --(DataPlayer!$E$2:$E$99941>0), --ISNUMBER(MATCH(DataPlayer!$A$2:$A$99941,_xlfn.ANCHORARRAY($A$2),0)) )} -> 0 | F25: {=SUMPRODUCT( DataPlayer!$F$2:$F$99941, --(DataPlayer!$C$2:$C$99941=C25), --ISNUMBER(MATCH(DataPlayer!$A$2:$A$99941,_xlfn.ANCHORARRAY($A$2),0)) )} -> 0 | G25: {=SUMPRODUCT( DataPlayer!$G$2:$G$99941, --(DataPlayer!$C$2:$C$99941=C25), --ISNUMBER(MATCH(DataPlayer!$A$2:$A$99941,_xlfn.ANCHORARRAY($A$2),0)) )} -> 0 | H25: =F25+G25 -> 0 | I25: {=SUMPRODUCT( --(DataPlayer!$C$2:$C$99941=C25), --(DataPlayer!$H$2:$H$99941="x"), --ISNUMBER(MATCH(DataPlayer!$A$2:$A$99941,_xlfn.ANCHORARRAY($A$2),0)) )} -> 0 | J25: {=IFERROR( AVERAGE( _xlfn._xlws.FILTER( DataPlayer!$E$2:$E$99941, (DataPlayer!$C$2:$C$99941=C25) * ISNUMBER(MATCH(DataPlayer!$A$2:$A$99941,_xlfn.ANCHORARRAY($A$2),0)) ) ), "" )}
E26: {=SUMPRODUCT( --(DataPlayer!$C$2:$C$99941=$C26), --(DataPlayer!$E$2:$E$99941>0), --ISNUMBER(MATCH(DataPlayer!$A$2:$A$99941,_xlfn.ANCHORARRAY($A$2),0)) )} -> 0 | F26: {=SUMPRODUCT( DataPlayer!$F$2:$F$99941, --(DataPlayer!$C$2:$C$99941=C26), --ISNUMBER(MATCH(DataPlayer!$A$2:$A$99941,_xlfn.ANCHORARRAY($A$2),0)) )} -> 0 | G26: {=SUMPRODUCT( DataPlayer!$G$2:$G$99941, --(DataPlayer!$C$2:$C$99941=C26), --ISNUMBER(MATCH(DataPlayer!$A$2:$A$99941,_xlfn.ANCHORARRAY($A$2),0)) )} -> 0 | H26: =F26+G26 -> 0 | I26: {=SUMPRODUCT( --(DataPlayer!$C$2:$C$99941=C26), --(DataPlayer!$H$2:$H$99941="x"), --ISNUMBER(MATCH(DataPlayer!$A$2:$A$99941,_xlfn.ANCHORARRAY($A$2),0)) )} -> 0 | J26: {=IFERROR( AVERAGE( _xlfn._xlws.FILTER( DataPlayer!$E$2:$E$99941, (DataPlayer!$C$2:$C$99941=C26) * ISNUMBER(MATCH(DataPlayer!$A$2:$A$99941,_xlfn.ANCHORARRAY($A$2),0)) ) ), "" )}
C28: Current Record | G28: Goals Difference | J28: Clean Sheets
C29: Won | D29: Lost | E29: Draw | G29: Scored | H29: Conceded
C30: {=SUM( --( _xlfn.XLOOKUP(_xlfn.ANCHORARRAY( $A$2), DataGames!$A$2:$A$99987, DataGames!$H$2:$H$99987, "" ) ="Win" ) )} -> 0 | D30: {=SUM( --( _xlfn.XLOOKUP(_xlfn.ANCHORARRAY( $A$2), DataGames!$A$2:$A$99987, DataGames!$H$2:$H$99987, "" ) ="Loss" ) )} -> 0 | E30: {=SUM( --( _xlfn.XLOOKUP(_xlfn.ANCHORARRAY( $A$2), DataGames!$A$2:$A$99987, DataGames!$H$2:$H$99987, "" ) ="Draw" ) )} -> 1 | G30: {=_xlfn.LET( _xlpm.Ort,_xlfn.XLOOKUP(_xlfn.ANCHORARRAY($A$2),DataGames!$A$2:$A$99987,DataGames!$I$2:$I$99987,""), _xlpm.Heim,_xlfn.XLOOKUP(_xlfn.ANCHORARRAY($A$2),DataGames!$A$2:$A$99987,DataGames!$D$2:$D$99987,0), _xlpm.Gast,_xlfn.XLOOKUP(_xlfn.ANCHORARRAY($A$2),DataGames!$A$2:$A$99987,DataGames!$E$2:$E$99987,0), SUM(--(_xlpm.Ort="Heim")*_xlpm.Heim)+SUM(--(_xlpm.Ort="Gast")*_xlpm.Gast) )} -> 5 | H30: {=_xlfn.LET( _xlpm.Ort,_xlfn.XLOOKUP(_xlfn.ANCHORARRAY($A$2),DataGames!$A$2:$A$99987,DataGames!$I$2:$I$99987,""), _xlpm.D,_xlfn.XLOOKUP(_xlfn.ANCHORARRAY($A$2),DataGames!$A$2:$A$99987,DataGames!$D$2:$D$99987,0), _xlpm.E,_xlfn.XLOOKUP(_xlfn.ANCHORARRAY($A$2),DataGames!$A$2:$A$99987,DataGames!$E$2:$E$99987,0), SUM(--(_xlpm.Ort="Gast")*_xlpm.D)+SUM(--(_xlpm.Ort="Heim")*_xlpm.E) )} -> 5 | J30: {=SUM( --( _xlfn.XLOOKUP(_xlfn.ANCHORARRAY( $A$2), DataGames!$A$2:$A$99987, DataGames!$Z$2:$Z$99987, "" ) ="ja" ) )} -> 0
C32: Rage Quit | D32: ET | G32: Avg Goals | H32: Avg Goals
C33: {=SUM( --( _xlfn.XLOOKUP(_xlfn.ANCHORARRAY( $A$2), DataGames!$A$2:$A$99987, DataGames!$X$2:$X$99987, "" ) ="Opponent quit (win)" ) )} -> 0 | G33: =G30/E4 -> 5 | H33: =H30/E4 -> 5 | J33: Avg. Posession
J35: {=IFERROR( AVERAGE( _xlfn.XLOOKUP(_xlfn.ANCHORARRAY( $A$2), DataGames!$A$2:$A$99987, DataGames!$J$2:$J$99987, "" ) ), " " )} -> 0.52
G36: Max Win Streak | H36: =_xlfn.MAXIFS(E57:E71,D57:D71,"Win") -> 0
C39: Top Goals | D39: =INDEX(C4:C22,MATCH(D41,F4:F22,0)) -> J. Cruyff | E39: =INDEX(C4:C22,MATCH(E41,F4:F22,0)) -> J. Cruyff | F39: =INDEX(C4:C22,MATCH(F41,F4:F22,0)) -> C. Pina | H39: Top Contributions | J39: Most MOTM
D41: =LARGE(F1:F21, 1) -> 2 | E41: =LARGE(F1:F21, 2) -> 2 | F41: =LARGE(F1:F21, 3) -> 1 | H41: =INDEX(C4:C22,MATCH(H43,H4:H22,0)) -> C. Pina | J41: =INDEX(C4:C22,MATCH(J43,I4:I22,0)) -> J. Cruyff
H43: =LARGE(H4:H22,1) -> 4 | J43: =LARGE(I4:I22,1) -> 0
C44: Top Assist | D44: =INDEX(C4:C22,MATCH(D46,G4:G22,0)) -> C. Pina | E44: =INDEX(C4:C22,MATCH(E46,G4:G22,0)) -> M. Salah | F44: =INDEX(C4:C22,MATCH(F46,G4:G22,0)) -> J. Cruyff
D46: =LARGE($G$3:$G$22, 1) -> 3 | E46: =LARGE($G$3:$G$22, 2) -> 1 | F46: =LARGE($G$3:$G$22, 3) -> 0 | H46: xG | I46: For | J46: Against
H48: Total | I48: {=IFERROR( SUM( _xlfn.XLOOKUP(_xlfn.ANCHORARRAY( $A$2), DataGames!$A$2:$A$99987, DataGames!$O$2:$O$99987, 0 ) ), " " )} -> 2.3 | J48: {=IFERROR( SUM( _xlfn.XLOOKUP(_xlfn.ANCHORARRAY( $A$2), DataGames!$A$2:$A$99987, DataGames!$P$2:$P$99987, 0 ) ), " " )} -> 0
C49: Best Avg. Rating | D49: =INDEX(C4:C22,MATCH(D51,J4:J22,0)) -> C. Pina | E49: =INDEX(C4:C22,MATCH(E51,J4:J22,0)) -> J. Cruyff | F49: =INDEX(C4:C22,MATCH(F51,J4:J22,0)) -> M. Salah | H49: Average | I49: {=IFERROR( AVERAGE( _xlfn.XLOOKUP(_xlfn.ANCHORARRAY( $A$2), DataGames!$A$2:$A$99987, DataGames!$O$2:$O$99987, "" ) ), " " )} -> 2.3 | J49: {=IFERROR( AVERAGE( _xlfn.XLOOKUP(_xlfn.ANCHORARRAY( $A$2), DataGames!$A$2:$A$99987, DataGames!$P$2:$P$99987, "" ) ), " " )}
...

Sheet DataGames
A1: MatchID | B1: MatchCategory | C1: Date | D1: HomeT | E1: AwayT | F1: Home | G1: Away | H1: Result | I1: Location | J1: Possession | K1: Shots | L1: ShotsOpp | M1: ShotAccuracy | N1: ShotAccuracyOpp | O1: xGoals | P1: xGoalsOpponent | Q1: Passes | R1: PassesOpp | S1: SuccessfulPasses | T1: SuccessfulPassesOpp | U1: SuccessfulDribbles | V1: YellowCards | W1: RedCards | X1: TerminationReason | Y1: MatchDuration | Z1: CleanSheet | AA1: ExtraTime | AB1: Unsicher/Fehlt
A2: RIV1 | B2: Rivals | C2: 46016 | D2: 5 | E2: 5 | F2: 2 Beards FC | G2: Momentum FC | H2: Draw | I2: Gast | J2: 0.52 | K2: 9 | M2: 0.89 | O2: 2.3 | Q2: 200 | S2: 0.87 | U2: 0.96 | V2: 0 | W2: 0 | Z2: nein

Sheet DataPlayer
A1: MatchID | B1: MatchCategory | C1: Name | D1: Position | E1: Rating | F1: Goals | G1: Assists | H1: MOTM | I1: Unsicher/Fehlt
A2: RIV1 | B2: Rivals | C2: P. Dybala | D2: ST | E2: 6.5 | F2: 0 | G2: 0
A3: RIV1 | B3: Rivals | C3: C. Pina | D3: ST | E3: 9.4 | F3: 1 | G3: 3 | H3: Ball-Icon nicht eindeutig erkennbar
A4: RIV1 | B4: Rivals | C4: G. Reiten | D4: ZOM | E4: 5.7 | F4: 0 | G4: 0
A5: RIV1 | B5: Rivals | C5: J. Cruyff | D5: ZOM | E5: 8.5 | F5: 2 | G5: 0
A6: RIV1 | B6: Rivals | C6: S. Mané | D6: LM | E6: 6.2 | F6: 0 | G6: 0
A7: RIV1 | B7: Rivals | C7: H. Kewell | D7: LM | E7: 7.1 | F7: 0 | G7: 1
A8: RIV1 | B8: Rivals | C8: J. Scott | D8: LZM | E8: 7.3 | F8: 0 | G8: 0
A9: RIV1 | B9: Rivals | C9: F. Valverde | D9: RZM | E9: 6.7 | F9: 0 | G9: 0
A10: RIV1 | B10: Rivals | C10: D. Sinani | D10: RM | E10: 6.8 | F10: 0 | G10: 0
A11: RIV1 | B11: Rivals | C11: M. Salah | D11: RM | E11: 8.3 | F11: 2 | G11: 1
A12: RIV1 | B12: Rivals | C12: J. Alba | D12: LV | E12: 6.8 | F12: 0 | G12: 0
A13: RIV1 | B13: Rivals | C13: W. Pacho | D13: LIV | E13: 6.8 | F13: 0 | G13: 0
A14: RIV1 | B14: Rivals | C14: G. Chiellini | D14: RIV | E14: 7.7 | F14: 0 | G14: 0
A15: RIV1 | B15: Rivals | C15: G. Zambrotta | D15: RV | E15: 6.5 | F15: 0 | G15: 0
A16: RIV1 | B16: Rivals | C16: T. Courtois | D16: TW | E16: 4 | F16: 0 | G16: 0
A17: RIV1 | B17: Rivals | C17: J. Tah | D17: AW | F17: 0 | G17: 0 | I17: Bewertung als N.V. angezeigt
A18: RIV1 | B18: Rivals | C18: H. Sawa | D18: AW | F18: 0 | G18: 0 | I18: Bewertung als N.V. angezeigt
A19: RIV1 | B19: Rivals | C19: Y. Hasegawa | D19: AW | F19: 0 | G19: 0 | I19: Bewertung als N.V. angezeigt

Sheet Readme
B2: © by Zuphael
B3: Always check the Source: | D3: https://github.com/Zuphael/eafcAIStats/
B4: Version 1: 5th January 2026
